Workbook

Sheet RESUMEN
A2: 121 | C2: PROCESO DE COMERCIALIZACIÓN ORDEN PEDIDO DE HUEVO | R2: CÓDIGO | S2: F-CD-04
R3: VERSIÓN | S3: 5
R4: FECHA | S4: 45239
R5: PAGINA | S5: 1 DE 1
A6: CLIENTE: | P6: FECHA DE PEDIDO: | R6: =+(TODAY()) -> 46066
A7: REFERENCIA | B7: TIPO | C7: ESTUCHE | H7: VITAFILM | L7: AMARRADO | Q7: SUELTO | R7: OBSERVACIONES
C8: 6 | D8: 12 | E8: 15 | F8: 20 | G8: 30 | H8: 15 | I8: 20 | J8: 30 | K8: 60 | L8: 15 | M8: 30 | N8: 45 | O8: 60 | P8: 180 | Q8: 1
A9: MARCA ORO | B9: AAAA | C9: =IF('cuadro 1'!C9+'cuadro 2'!C9+'cuadro 3'!C9=0,"",'cuadro 1'!C9+'cuadro 2'!C9+'cuadro 3'!C9) | D9: =IF('cuadro 1'!D9+'cuadro 2'!D9+'cuadro 3'!D9=0,"",'cuadro 1'!D9+'cuadro 2'!D9+'cuadro 3'!D9) | E9: =IF('cuadro 1'!E9+'cuadro 2'!E9+'cuadro 3'!E9=0,"",'cuadro 1'!E9+'cuadro 2'!E9+'cuadro 3'!E9) | F9: =IF('cuadro 1'!F9+'cuadro 2'!F9+'cuadro 3'!F9=0,"",'cuadro 1'!F9+'cuadro 2'!F9+'cuadro 3'!F9) | G9: =IF('cuadro 1'!G9+'cuadro 2'!G9+'cuadro 3'!G9=0,"",'cuadro 1'!G9+'cuadro 2'!G9+'cuadro 3'!G9) | H9: =IF('cuadro 1'!H9+'cuadro 2'!H9+'cuadro 3'!H9=0,"",'cuadro 1'!H9+'cuadro 2'!H9+'cuadro 3'!H9) | I9: =IF('cuadro 1'!I9+'cuadro 2'!I9+'cuadro 3'!I9=0,"",'cuadro 1'!I9+'cuadro 2'!I9+'cuadro 3'!I9) -> 32 | J9: =IF('cuadro 1'!J9+'cuadro 2'!J9+'cuadro 3'!J9=0,"",'cuadro 1'!J9+'cuadro 2'!J9+'cuadro 3'!J9) | ... Q9: =IF('cuadro 1'!Q9+'cuadro 2'!Q9+'cuadro 3'!Q9=0,"",'cuadro 1'!Q9+'cuadro 2'!Q9+'cuadro 3'!Q9)
B10: AAA | C10: =IF('cuadro 1'!C10+'cuadro 2'!C10+'cuadro 3'!C10=0,"",'cuadro 1'!C10+'cuadro 2'!C10+'cuadro 3'!C10) | D10: =IF('cuadro 1'!D10+'cuadro 2'!D10+'cuadro 3'!D10=0,"",'cuadro 1'!D10+'cuadro 2'!D10+'cuadro 3'!D10) -> 40 | E10: =IF('cuadro 1'!E10+'cuadro 2'!E10+'cuadro 3'!E10=0,"",'cuadro 1'!E10+'cuadro 2'!E10+'cuadro 3'!E10) | F10: =IF('cuadro 1'!F10+'cuadro 2'!F10+'cuadro 3'!F10=0,"",'cuadro 1'!F10+'cuadro 2'!F10+'cuadro 3'!F10) | G10: =IF('cuadro 1'!G10+'cuadro 2'!G10+'cuadro 3'!G10=0,"",'cuadro 1'!G10+'cuadro 2'!G10+'cuadro 3'!G10) | H10: =IF('cuadro 1'!H10+'cuadro 2'!H10+'cuadro 3'!H10=0,"",'cuadro 1'!H10+'cuadro 2'!H10+'cuadro 3'!H10) | I10: =IF('cuadro 1'!I10+'cuadro 2'!I10+'cuadro 3'!I10=0,"",'cuadro 1'!I10+'cuadro 2'!I10+'cuadro 3'!I10) | J10: =IF('cuadro 1'!J10+'cuadro 2'!J10+'cuadro 3'!J10=0,"",'cuadro 1'!J10+'cuadro 2'!J10+'cuadro 3'!J10) | ... Q10: =IF('cuadro 1'!Q10+'cuadro 2'!Q10+'cuadro 3'!Q10=0,"",'cuadro 1'!Q10+'cuadro 2'!Q10+'cuadro 3'!Q10)
B11: AA | C11: =IF('cuadro 1'!C11+'cuadro 2'!C11+'cuadro 3'!C11=0,"",'cuadro 1'!C11+'cuadro 2'!C11+'cuadro 3'!C11) -> 23 | D11: =IF('cuadro 1'!D11+'cuadro 2'!D11+'cuadro 3'!D11=0,"",'cuadro 1'!D11+'cuadro 2'!D11+'cuadro 3'!D11) | E11: =IF('cuadro 1'!E11+'cuadro 2'!E11+'cuadro 3'!E11=0,"",'cuadro 1'!E11+'cuadro 2'!E11+'cuadro 3'!E11) | F11: =IF('cuadro 1'!F11+'cuadro 2'!F11+'cuadro 3'!F11=0,"",'cuadro 1'!F11+'cuadro 2'!F11+'cuadro 3'!F11) | G11: =IF('cuadro 1'!G11+'cuadro 2'!G11+'cuadro 3'!G11=0,"",'cuadro 1'!G11+'cuadro 2'!G11+'cuadro 3'!G11) | H11: =IF('cuadro 1'!H11+'cuadro 2'!H11+'cuadro 3'!H11=0,"",'cuadro 1'!H11+'cuadro 2'!H11+'cuadro 3'!H11) | I11: =IF('cuadro 1'!I11+'cuadro 2'!I11+'cuadro 3'!I11=0,"",'cuadro 1'!I11+'cuadro 2'!I11+'cuadro 3'!I11) | J11: =IF('cuadro 1'!J11+'cuadro 2'!J11+'cuadro 3'!J11=0,"",'cuadro 1'!J11+'cuadro 2'!J11+'cuadro 3'!J11) | ... Q11: =IF('cuadro 1'!Q11+'cuadro 2'!Q11+'cuadro 3'!Q11=0,"",'cuadro 1'!Q11+'cuadro 2'!Q11+'cuadro 3'!Q11)
B12: A | C12: =IF('cuadro 1'!C12+'cuadro 2'!C12+'cuadro 3'!C12=0,"",'cuadro 1'!C12+'cuadro 2'!C12+'cuadro 3'!C12) | D12: =IF('cuadro 1'!D12+'cuadro 2'!D12+'cuadro 3'!D12=0,"",'cuadro 1'!D12+'cuadro 2'!D12+'cuadro 3'!D12) | E12: =IF('cuadro 1'!E12+'cuadro 2'!E12+'cuadro 3'!E12=0,"",'cuadro 1'!E12+'cuadro 2'!E12+'cuadro 3'!E12) | F12: =IF('cuadro 1'!F12+'cuadro 2'!F12+'cuadro 3'!F12=0,"",'cuadro 1'!F12+'cuadro 2'!F12+'cuadro 3'!F12) | G12: =IF('cuadro 1'!G12+'cuadro 2'!G12+'cuadro 3'!G12=0,"",'cuadro 1'!G12+'cuadro 2'!G12+'cuadro 3'!G12) | H12: =IF('cuadro 1'!H12+'cuadro 2'!H12+'cuadro 3'!H12=0,"",'cuadro 1'!H12+'cuadro 2'!H12+'cuadro 3'!H12) | I12: =IF('cuadro 1'!I12+'cuadro 2'!I12+'cuadro 3'!I12=0,"",'cuadro 1'!I12+'cuadro 2'!I12+'cuadro 3'!I12) | J12: =IF('cuadro 1'!J12+'cuadro 2'!J12+'cuadro 3'!J12=0,"",'cuadro 1'!J12+'cuadro 2'!J12+'cuadro 3'!J12) | ... Q12: =IF('cuadro 1'!Q12+'cuadro 2'!Q12+'cuadro 3'!Q12=0,"",'cuadro 1'!Q12+'cuadro 2'!Q12+'cuadro 3'!Q12)
B13: B | C13: =IF('cuadro 1'!C13+'cuadro 2'!C13+'cuadro 3'!C13=0,"",'cuadro 1'!C13+'cuadro 2'!C13+'cuadro 3'!C13) | D13: =IF('cuadro 1'!D13+'cuadro 2'!D13+'cuadro 3'!D13=0,"",'cuadro 1'!D13+'cuadro 2'!D13+'cuadro 3'!D13) | E13: =IF('cuadro 1'!E13+'cuadro 2'!E13+'cuadro 3'!E13=0,"",'cuadro 1'!E13+'cuadro 2'!E13+'cuadro 3'!E13) | F13: =IF('cuadro 1'!F13+'cuadro 2'!F13+'cuadro 3'!F13=0,"",'cuadro 1'!F13+'cuadro 2'!F13+'cuadro 3'!F13) | G13: =IF('cuadro 1'!G13+'cuadro 2'!G13+'cuadro 3'!G13=0,"",'cuadro 1'!G13+'cuadro 2'!G13+'cuadro 3'!G13) | H13: =IF('cuadro 1'!H13+'cuadro 2'!H13+'cuadro 3'!H13=0,"",'cuadro 1'!H13+'cuadro 2'!H13+'cuadro 3'!H13) | I13: =IF('cuadro 1'!I13+'cuadro 2'!I13+'cuadro 3'!I13=0,"",'cuadro 1'!I13+'cuadro 2'!I13+'cuadro 3'!I13) | J13: =IF('cuadro 1'!J13+'cuadro 2'!J13+'cuadro 3'!J13=0,"",'cuadro 1'!J13+'cuadro 2'!J13+'cuadro 3'!J13) | ... Q13: =IF('cuadro 1'!Q13+'cuadro 2'!Q13+'cuadro 3'!Q13=0,"",'cuadro 1'!Q13+'cuadro 2'!Q13+'cuadro 3'!Q13)
B14: C | C14: =IF('cuadro 1'!C14+'cuadro 2'!C14+'cuadro 3'!C14=0,"",'cuadro 1'!C14+'cuadro 2'!C14+'cuadro 3'!C14) | D14: =IF('cuadro 1'!D14+'cuadro 2'!D14+'cuadro 3'!D14=0,"",'cuadro 1'!D14+'cuadro 2'!D14+'cuadro 3'!D14) | E14: =IF('cuadro 1'!E14+'cuadro 2'!E14+'cuadro 3'!E14=0,"",'cuadro 1'!E14+'cuadro 2'!E14+'cuadro 3'!E14) | F14: =IF('cuadro 1'!F14+'cuadro 2'!F14+'cuadro 3'!F14=0,"",'cuadro 1'!F14+'cuadro 2'!F14+'cuadro 3'!F14) | G14: =IF('cuadro 1'!G14+'cuadro 2'!G14+'cuadro 3'!G14=0,"",'cuadro 1'!G14+'cuadro 2'!G14+'cuadro 3'!G14) | H14: =IF('cuadro 1'!H14+'cuadro 2'!H14+'cuadro 3'!H14=0,"",'cuadro 1'!H14+'cuadro 2'!H14+'cuadro 3'!H14) | I14: =IF('cuadro 1'!I14+'cuadro 2'!I14+'cuadro 3'!I14=0,"",'cuadro 1'!I14+'cuadro 2'!I14+'cuadro 3'!I14) | J14: =IF('cuadro 1'!J14+'cuadro 2'!J14+'cuadro 3'!J14=0,"",'cuadro 1'!J14+'cuadro 2'!J14+'cuadro 3'!J14) | ... Q14: =IF('cuadro 1'!Q14+'cuadro 2'!Q14+'cuadro 3'!Q14=0,"",'cuadro 1'!Q14+'cuadro 2'!Q14+'cuadro 3'!Q14)
A15: PLUS | B15: AAA | C15: =IF('cuadro 1'!C15+'cuadro 2'!C15+'cuadro 3'!C15=0,"",'cuadro 1'!C15+'cuadro 2'!C15+'cuadro 3'!C15) | D15: =IF('cuadro 1'!D15+'cuadro 2'!D15+'cuadro 3'!D15=0,"",'cuadro 1'!D15+'cuadro 2'!D15+'cuadro 3'!D15) -> 108 | E15: =IF('cuadro 1'!E15+'cuadro 2'!E15+'cuadro 3'!E15=0,"",'cuadro 1'!E15+'cuadro 2'!E15+'cuadro 3'!E15) -> 48 | F15: =IF('cuadro 1'!F15+'cuadro 2'!F15+'cuadro 3'!F15=0,"",'cuadro 1'!F15+'cuadro 2'!F15+'cuadro 3'!F15) | G15: =IF('cuadro 1'!G15+'cuadro 2'!G15+'cuadro 3'!G15=0,"",'cuadro 1'!G15+'cuadro 2'!G15+'cuadro 3'!G15) | H15: =IF('cuadro 1'!H15+'cuadro 2'!H15+'cuadro 3'!H15=0,"",'cuadro 1'!H15+'cuadro 2'!H15+'cuadro 3'!H15) | I15: =IF('cuadro 1'!I15+'cuadro 2'!I15+'cuadro 3'!I15=0,"",'cuadro 1'!I15+'cuadro 2'!I15+'cuadro 3'!I15) | J15: =IF('cuadro 1'!J15+'cuadro 2'!J15+'cuadro 3'!J15=0,"",'cuadro 1'!J15+'cuadro 2'!J15+'cuadro 3'!J15) -> 131 | ... Q15: =IF('cuadro 1'!Q15+'cuadro 2'!Q15+'cuadro 3'!Q15=0,"",'cuadro 1'!Q15+'cuadro 2'!Q15+'cuadro 3'!Q15)
B16: AA | C16: =IF('cuadro 1'!C16+'cuadro 2'!C16+'cuadro 3'!C16=0,"",'cuadro 1'!C16+'cuadro 2'!C16+'cuadro 3'!C16) | D16: =IF('cuadro 1'!D16+'cuadro 2'!D16+'cuadro 3'!D16=0,"",'cuadro 1'!D16+'cuadro 2'!D16+'cuadro 3'!D16) | E16: =IF('cuadro 1'!E16+'cuadro 2'!E16+'cuadro 3'!E16=0,"",'cuadro 1'!E16+'cuadro 2'!E16+'cuadro 3'!E16) | F16: =IF('cuadro 1'!F16+'cuadro 2'!F16+'cuadro 3'!F16=0,"",'cuadro 1'!F16+'cuadro 2'!F16+'cuadro 3'!F16) | G16: =IF('cuadro 1'!G16+'cuadro 2'!G16+'cuadro 3'!G16=0,"",'cuadro 1'!G16+'cuadro 2'!G16+'cuadro 3'!G16) | H16: =IF('cuadro 1'!H16+'cuadro 2'!H16+'cuadro 3'!H16=0,"",'cuadro 1'!H16+'cuadro 2'!H16+'cuadro 3'!H16) | I16: =IF('cuadro 1'!I16+'cuadro 2'!I16+'cuadro 3'!I16=0,"",'cuadro 1'!I16+'cuadro 2'!I16+'cuadro 3'!I16) | J16: =IF('cuadro 1'!J16+'cuadro 2'!J16+'cuadro 3'!J16=0,"",'cuadro 1'!J16+'cuadro 2'!J16+'cuadro 3'!J16) -> 30 | ... Q16: =IF('cuadro 1'!Q16+'cuadro 2'!Q16+'cuadro 3'!Q16=0,"",'cuadro 1'!Q16+'cuadro 2'!Q16+'cuadro 3'!Q16)
A17: CAMPESINO | B17: AA | C17: =IF('cuadro 1'!C17+'cuadro 2'!C17+'cuadro 3'!C17=0,"",'cuadro 1'!C17+'cuadro 2'!C17+'cuadro 3'!C17) | D17: =IF('cuadro 1'!D17+'cuadro 2'!D17+'cuadro 3'!D17=0,"",'cuadro 1'!D17+'cuadro 2'!D17+'cuadro 3'!D17) -> 55 | E17: =IF('cuadro 1'!E17+'cuadro 2'!E17+'cuadro 3'!E17=0,"",'cuadro 1'!E17+'cuadro 2'!E17+'cuadro 3'!E17) | F17: =IF('cuadro 1'!F17+'cuadro 2'!F17+'cuadro 3'!F17=0,"",'cuadro 1'!F17+'cuadro 2'!F17+'cuadro 3'!F17) | G17: =IF('cuadro 1'!G17+'cuadro 2'!G17+'cuadro 3'!G17=0,"",'cuadro 1'!G17+'cuadro 2'!G17+'cuadro 3'!G17) | H17: =IF('cuadro 1'!H17+'cuadro 2'!H17+'cuadro 3'!H17=0,"",'cuadro 1'!H17+'cuadro 2'!H17+'cuadro 3'!H17) | I17: =IF('cuadro 1'!I17+'cuadro 2'!I17+'cuadro 3'!I17=0,"",'cuadro 1'!I17+'cuadro 2'!I17+'cuadro 3'!I17) | J17: =IF('cuadro 1'!J17+'cuadro 2'!J17+'cuadro 3'!J17=0,"",'cuadro 1'!J17+'cuadro 2'!J17+'cuadro 3'!J17) -> 380 | ... Q17: =IF('cuadro 1'!Q17+'cuadro 2'!Q17+'cuadro 3'!Q17=0,"",'cuadro 1'!Q17+'cuadro 2'!Q17+'cuadro 3'!Q17)
B18: A | C18: =IF('cuadro 1'!C18+'cuadro 2'!C18+'cuadro 3'!C18=0,"",'cuadro 1'!C18+'cuadro 2'!C18+'cuadro 3'!C18) | D18: =IF('cuadro 1'!D18+'cuadro 2'!D18+'cuadro 3'!D18=0,"",'cuadro 1'!D18+'cuadro 2'!D18+'cuadro 3'!D18) | E18: =IF('cuadro 1'!E18+'cuadro 2'!E18+'cuadro 3'!E18=0,"",'cuadro 1'!E18+'cuadro 2'!E18+'cuadro 3'!E18) | F18: =IF('cuadro 1'!F18+'cuadro 2'!F18+'cuadro 3'!F18=0,"",'cuadro 1'!F18+'cuadro 2'!F18+'cuadro 3'!F18) | G18: =IF('cuadro 1'!G18+'cuadro 2'!G18+'cuadro 3'!G18=0,"",'cuadro 1'!G18+'cuadro 2'!G18+'cuadro 3'!G18) | H18: =IF('cuadro 1'!H18+'cuadro 2'!H18+'cuadro 3'!H18=0,"",'cuadro 1'!H18+'cuadro 2'!H18+'cuadro 3'!H18) | I18: =IF('cuadro 1'!I18+'cuadro 2'!I18+'cuadro 3'!I18=0,"",'cuadro 1'!I18+'cuadro 2'!I18+'cuadro 3'!I18) | J18: =IF('cuadro 1'!J18+'cuadro 2'!J18+'cuadro 3'!J18=0,"",'cuadro 1'!J18+'cuadro 2'!J18+'cuadro 3'!J18) | ... Q18: =IF('cuadro 1'!Q18+'cuadro 2'!Q18+'cuadro 3'!Q18=0,"",'cuadro 1'!Q18+'cuadro 2'!Q18+'cuadro 3'!Q18)
A19: KOSHER | B19: AA-A | C19: =IF('cuadro 1'!C19+'cuadro 2'!C19+'cuadro 3'!C19=0,"",'cuadro 1'!C19+'cuadro 2'!C19+'cuadro 3'!C19) | D19: =IF('cuadro 1'!D19+'cuadro 2'!D19+'cuadro 3'!D19=0,"",'cuadro 1'!D19+'cuadro 2'!D19+'cuadro 3'!D19) | E19: =IF('cuadro 1'!E19+'cuadro 2'!E19+'cuadro 3'!E19=0,"",'cuadro 1'!E19+'cuadro 2'!E19+'cuadro 3'!E19) | F19: =IF('cuadro 1'!F19+'cuadro 2'!F19+'cuadro 3'!F19=0,"",'cuadro 1'!F19+'cuadro 2'!F19+'cuadro 3'!F19) | G19: =IF('cuadro 1'!G19+'cuadro 2'!G19+'cuadro 3'!G19=0,"",'cuadro 1'!G19+'cuadro 2'!G19+'cuadro 3'!G19) | H19: =IF('cuadro 1'!H19+'cuadro 2'!H19+'cuadro 3'!H19=0,"",'cuadro 1'!H19+'cuadro 2'!H19+'cuadro 3'!H19) | I19: =IF('cuadro 1'!I19+'cuadro 2'!I19+'cuadro 3'!I19=0,"",'cuadro 1'!I19+'cuadro 2'!I19+'cuadro 3'!I19) | J19: =IF('cuadro 1'!J19+'cuadro 2'!J19+'cuadro 3'!J19=0,"",'cuadro 1'!J19+'cuadro 2'!J19+'cuadro 3'!J19) -> 111 | ... Q19: =IF('cuadro 1'!Q19+'cuadro 2'!Q19+'cuadro 3'!Q19=0,"",'cuadro 1'!Q19+'cuadro 2'!Q19+'cuadro 3'!Q19)
A20: DHA | B20: AA-A | C20: =IF('cuadro 1'!C20+'cuadro 2'!C20+'cuadro 3'!C20=0,"",'cuadro 1'!C20+'cuadro 2'!C20+'cuadro 3'!C20) | D20: =IF('cuadro 1'!D20+'cuadro 2'!D20+'cuadro 3'!D20=0,"",'cuadro 1'!D20+'cuadro 2'!D20+'cuadro 3'!D20) -> 13 | E20: =IF('cuadro 1'!E20+'cuadro 2'!E20+'cuadro 3'!E20=0,"",'cuadro 1'!E20+'cuadro 2'!E20+'cuadro 3'!E20) | F20: =IF('cuadro 1'!F20+'cuadro 2'!F20+'cuadro 3'!F20=0,"",'cuadro 1'!F20+'cuadro 2'!F20+'cuadro 3'!F20) | G20: =IF('cuadro 1'!G20+'cuadro 2'!G20+'cuadro 3'!G20=0,"",'cuadro 1'!G20+'cuadro 2'!G20+'cuadro 3'!G20) | H20: =IF('cuadro 1'!H20+'cuadro 2'!H20+'cuadro 3'!H20=0,"",'cuadro 1'!H20+'cuadro 2'!H20+'cuadro 3'!H20) | I20: =IF('cuadro 1'!I20+'cuadro 2'!I20+'cuadro 3'!I20=0,"",'cuadro 1'!I20+'cuadro 2'!I20+'cuadro 3'!I20) | J20: =IF('cuadro 1'!J20+'cuadro 2'!J20+'cuadro 3'!J20=0,"",'cuadro 1'!J20+'cuadro 2'!J20+'cuadro 3'!J20) | ... Q20: =IF('cuadro 1'!Q20+'cuadro 2'!Q20+'cuadro 3'!Q20=0,"",'cuadro 1'!Q20+'cuadro 2'!Q20+'cuadro 3'!Q20)
A21: SELENIO | B21: AA-A | C21: =IF('cuadro 1'!C21+'cuadro 2'!C21+'cuadro 3'!C21=0,"",'cuadro 1'!C21+'cuadro 2'!C21+'cuadro 3'!C21) | D21: =IF('cuadro 1'!D21+'cuadro 2'!D21+'cuadro 3'!D21=0,"",'cuadro 1'!D21+'cuadro 2'!D21+'cuadro 3'!D21) -> 23 | E21: =IF('cuadro 1'!E21+'cuadro 2'!E21+'cuadro 3'!E21=0,"",'cuadro 1'!E21+'cuadro 2'!E21+'cuadro 3'!E21) | F21: =IF('cuadro 1'!F21+'cuadro 2'!F21+'cuadro 3'!F21=0,"",'cuadro 1'!F21+'cuadro 2'!F21+'cuadro 3'!F21) | G21: =IF('cuadro 1'!G21+'cuadro 2'!G21+'cuadro 3'!G21=0,"",'cuadro 1'!G21+'cuadro 2'!G21+'cuadro 3'!G21) | H21: =IF('cuadro 1'!H21+'cuadro 2'!H21+'cuadro 3'!H21=0,"",'cuadro 1'!H21+'cuadro 2'!H21+'cuadro 3'!H21) | I21: =IF('cuadro 1'!I21+'cuadro 2'!I21+'cuadro 3'!I21=0,"",'cuadro 1'!I21+'cuadro 2'!I21+'cuadro 3'!I21) | J21: =IF('cuadro 1'!J21+'cuadro 2'!J21+'cuadro 3'!J21=0,"",'cuadro 1'!J21+'cuadro 2'!J21+'cuadro 3'!J21) | ... Q21: =IF('cuadro 1'!Q21+'cuadro 2'!Q21+'cuadro 3'!Q21=0,"",'cuadro 1'!Q21+'cuadro 2'!Q21+'cuadro 3'!Q21)
A22: JUNIOR | B22: A | C22: =IF('cuadro 1'!C22+'cuadro 2'!C22+'cuadro 3'!C22=0,"",'cuadro 1'!C22+'cuadro 2'!C22+'cuadro 3'!C22) | D22: =IF('cuadro 1'!D22+'cuadro 2'!D22+'cuadro 3'!D22=0,"",'cuadro 1'!D22+'cuadro 2'!D22+'cuadro 3'!D22) | E22: =IF('cuadro 1'!E22+'cuadro 2'!E22+'cuadro 3'!E22=0,"",'cuadro 1'!E22+'cuadro 2'!E22+'cuadro 3'!E22) | F22: =IF('cuadro 1'!F22+'cuadro 2'!F22+'cuadro 3'!F22=0,"",'cuadro 1'!F22+'cuadro 2'!F22+'cuadro 3'!F22) | G22: =IF('cuadro 1'!G22+'cuadro 2'!G22+'cuadro 3'!G22=0,"",'cuadro 1'!G22+'cuadro 2'!G22+'cuadro 3'!G22) | H22: =IF('cuadro 1'!H22+'cuadro 2'!H22+'cuadro 3'!H22=0,"",'cuadro 1'!H22+'cuadro 2'!H22+'cuadro 3'!H22) | I22: =IF('cuadro 1'!I22+'cuadro 2'!I22+'cuadro 3'!I22=0,"",'cuadro 1'!I22+'cuadro 2'!I22+'cuadro 3'!I22) | J22: =IF('cuadro 1'!J22+'cuadro 2'!J22+'cuadro 3'!J22=0,"",'cuadro 1'!J22+'cuadro 2'!J22+'cuadro 3'!J22) | ... Q22: =IF('cuadro 1'!Q22+'cuadro 2'!Q22+'cuadro 3'!Q22=0,"",'cuadro 1'!Q22+'cuadro 2'!Q22+'cuadro 3'!Q22)
A23: TAEQ | B23: AA | C23: =IF('cuadro 1'!C23+'cuadro 2'!C23+'cuadro 3'!C23=0,"",'cuadro 1'!C23+'cuadro 2'!C23+'cuadro 3'!C23) | D23: =IF('cuadro 1'!D23+'cuadro 2'!D23+'cuadro 3'!D23=0,"",'cuadro 1'!D23+'cuadro 2'!D23+'cuadro 3'!D23) | E23: =IF('cuadro 1'!E23+'cuadro 2'!E23+'cuadro 3'!E23=0,"",'cuadro 1'!E23+'cuadro 2'!E23+'cuadro 3'!E23) | F23: =IF('cuadro 1'!F23+'cuadro 2'!F23+'cuadro 3'!F23=0,"",'cuadro 1'!F23+'cuadro 2'!F23+'cuadro 3'!F23) | G23: =IF('cuadro 1'!G23+'cuadro 2'!G23+'cuadro 3'!G23=0,"",'cuadro 1'!G23+'cuadro 2'!G23+'cuadro 3'!G23) | H23: =IF('cuadro 1'!H23+'cuadro 2'!H23+'cuadro 3'!H23=0,"",'cuadro 1'!H23+'cuadro 2'!H23+'cuadro 3'!H23) | I23: =IF('cuadro 1'!I23+'cuadro 2'!I23+'cuadro 3'!I23=0,"",'cuadro 1'!I23+'cuadro 2'!I23+'cuadro 3'!I23) | J23: =IF('cuadro 1'!J23+'cuadro 2'!J23+'cuadro 3'!J23=0,"",'cuadro 1'!J23+'cuadro 2'!J23+'cuadro 3'!J23) | ... Q23: =IF('cuadro 1'!Q23+'cuadro 2'!Q23+'cuadro 3'!Q23=0,"",'cuadro 1'!Q23+'cuadro 2'!Q23+'cuadro 3'!Q23)
A24: OXXO | B24: AA | C24: =IF('cuadro 1'!C24+'cuadro 2'!C24+'cuadro 3'!C24=0,"",'cuadro 1'!C24+'cuadro 2'!C24+'cuadro 3'!C24) | D24: =IF('cuadro 1'!D24+'cuadro 2'!D24+'cuadro 3'!D24=0,"",'cuadro 1'!D24+'cuadro 2'!D24+'cuadro 3'!D24) | E24: =IF('cuadro 1'!E24+'cuadro 2'!E24+'cuadro 3'!E24=0,"",'cuadro 1'!E24+'cuadro 2'!E24+'cuadro 3'!E24) | F24: =IF('cuadro 1'!F24+'cuadro 2'!F24+'cuadro 3'!F24=0,"",'cuadro 1'!F24+'cuadro 2'!F24+'cuadro 3'!F24) | G24: =IF('cuadro 1'!G24+'cuadro 2'!G24+'cuadro 3'!G24=0,"",'cuadro 1'!G24+'cuadro 2'!G24+'cuadro 3'!G24) | H24: =IF('cuadro 1'!H24+'cuadro 2'!H24+'cuadro 3'!H24=0,"",'cuadro 1'!H24+'cuadro 2'!H24+'cuadro 3'!H24) | I24: =IF('cuadro 1'!I24+'cuadro 2'!I24+'cuadro 3'!I24=0,"",'cuadro 1'!I24+'cuadro 2'!I24+'cuadro 3'!I24) | J24: =IF('cuadro 1'!J24+'cuadro 2'!J24+'cuadro 3'!J24=0,"",'cuadro 1'!J24+'cuadro 2'!J24+'cuadro 3'!J24) | ... Q24: =IF('cuadro 1'!Q24+'cuadro 2'!Q24+'cuadro 3'!Q24=0,"",'cuadro 1'!Q24+'cuadro 2'!Q24+'cuadro 3'!Q24)
A25: OLIMPICA | B25: A | C25: =IF('cuadro 1'!C25+'cuadro 2'!C25+'cuadro 3'!C25=0,"",'cuadro 1'!C25+'cuadro 2'!C25+'cuadro 3'!C25) | D25: =IF('cuadro 1'!D25+'cuadro 2'!D25+'cuadro 3'!D25=0,"",'cuadro 1'!D25+'cuadro 2'!D25+'cuadro 3'!D25) | E25: =IF('cuadro 1'!E25+'cuadro 2'!E25+'cuadro 3'!E25=0,"",'cuadro 1'!E25+'cuadro 2'!E25+'cuadro 3'!E25) | F25: =IF('cuadro 1'!F25+'cuadro 2'!F25+'cuadro 3'!F25=0,"",'cuadro 1'!F25+'cuadro 2'!F25+'cuadro 3'!F25) | G25: =IF('cuadro 1'!G25+'cuadro 2'!G25+'cuadro 3'!G25=0,"",'cuadro 1'!G25+'cuadro 2'!G25+'cuadro 3'!G25) | H25: =IF('cuadro 1'!H25+'cuadro 2'!H25+'cuadro 3'!H25=0,"",'cuadro 1'!H25+'cuadro 2'!H25+'cuadro 3'!H25) | I25: =IF('cuadro 1'!I25+'cuadro 2'!I25+'cuadro 3'!I25=0,"",'cuadro 1'!I25+'cuadro 2'!I25+'cuadro 3'!I25) | J25: =IF('cuadro 1'!J25+'cuadro 2'!J25+'cuadro 3'!J25=0,"",'cuadro 1'!J25+'cuadro 2'!J25+'cuadro 3'!J25) | ... Q25: =IF('cuadro 1'!Q25+'cuadro 2'!Q25+'cuadro 3'!Q25=0,"",'cuadro 1'!Q25+'cuadro 2'!Q25+'cuadro 3'!Q25)
B26: B | C26: =IF('cuadro 1'!C26+'cuadro 2'!C26+'cuadro 3'!C26=0,"",'cuadro 1'!C26+'cuadro 2'!C26+'cuadro 3'!C26) | D26: =IF('cuadro 1'!D26+'cuadro 2'!D26+'cuadro 3'!D26=0,"",'cuadro 1'!D26+'cuadro 2'!D26+'cuadro 3'!D26) | E26: =IF('cuadro 1'!E26+'cuadro 2'!E26+'cuadro 3'!E26=0,"",'cuadro 1'!E26+'cuadro 2'!E26+'cuadro 3'!E26) | F26: =IF('cuadro 1'!F26+'cuadro 2'!F26+'cuadro 3'!F26=0,"",'cuadro 1'!F26+'cuadro 2'!F26+'cuadro 3'!F26) | G26: =IF('cuadro 1'!G26+'cuadro 2'!G26+'cuadro 3'!G26=0,"",'cuadro 1'!G26+'cuadro 2'!G26+'cuadro 3'!G26) | H26: =IF('cuadro 1'!H26+'cuadro 2'!H26+'cuadro 3'!H26=0,"",'cuadro 1'!H26+'cuadro 2'!H26+'cuadro 3'!H26) | I26: =IF('cuadro 1'!I26+'cuadro 2'!I26+'cuadro 3'!I26=0,"",'cuadro 1'!I26+'cuadro 2'!I26+'cuadro 3'!I26) | J26: =IF('cuadro 1'!J26+'cuadro 2'!J26+'cuadro 3'!J26=0,"",'cuadro 1'!J26+'cuadro 2'!J26+'cuadro 3'!J26) | ... Q26: =IF('cuadro 1'!Q26+'cuadro 2'!Q26+'cuadro 3'!Q26=0,"",'cuadro 1'!Q26+'cuadro 2'!Q26+'cuadro 3'!Q26)
A27: TAT | B27: A | C27: =IF('cuadro 1'!C27+'cuadro 2'!C27+'cuadro 3'!C27=0,"",'cuadro 1'!C27+'cuadro 2'!C27+'cuadro 3'!C27) | D27: =IF('cuadro 1'!D27+'cuadro 2'!D27+'cuadro 3'!D27=0,"",'cuadro 1'!D27+'cuadro 2'!D27+'cuadro 3'!D27) | E27: =IF('cuadro 1'!E27+'cuadro 2'!E27+'cuadro 3'!E27=0,"",'cuadro 1'!E27+'cuadro 2'!E27+'cuadro 3'!E27) | F27: =IF('cuadro 1'!F27+'cuadro 2'!F27+'cuadro 3'!F27=0,"",'cuadro 1'!F27+'cuadro 2'!F27+'cuadro 3'!F27) | G27: =IF('cuadro 1'!G27+'cuadro 2'!G27+'cuadro 3'!G27=0,"",'cuadro 1'!G27+'cuadro 2'!G27+'cuadro 3'!G27) | H27: =IF('cuadro 1'!H27+'cuadro 2'!H27+'cuadro 3'!H27=0,"",'cuadro 1'!H27+'cuadro 2'!H27+'cuadro 3'!H27) | I27: =IF('cuadro 1'!I27+'cuadro 2'!I27+'cuadro 3'!I27=0,"",'cuadro 1'!I27+'cuadro 2'!I27+'cuadro 3'!I27) | J27: =IF('cuadro 1'!J27+'cuadro 2'!J27+'cuadro 3'!J27=0,"",'cuadro 1'!J27+'cuadro 2'!J27+'cuadro 3'!J27) | ... Q27: =IF('cuadro 1'!Q27+'cuadro 2'!Q27+'cuadro 3'!Q27=0,"",'cuadro 1'!Q27+'cuadro 2'!Q27+'cuadro 3'!Q27)
B28: AA | C28: =IF('cuadro 1'!C28+'cuadro 2'!C28+'cuadro 3'!C28=0,"",'cuadro 1'!C28+'cuadro 2'!C28+'cuadro 3'!C28) | D28: =IF('cuadro 1'!D28+'cuadro 2'!D28+'cuadro 3'!D28=0,"",'cuadro 1'!D28+'cuadro 2'!D28+'cuadro 3'!D28) | E28: =IF('cuadro 1'!E28+'cuadro 2'!E28+'cuadro 3'!E28=0,"",'cuadro 1'!E28+'cuadro 2'!E28+'cuadro 3'!E28) | F28: =IF('cuadro 1'!F28+'cuadro 2'!F28+'cuadro 3'!F28=0,"",'cuadro 1'!F28+'cuadro 2'!F28+'cuadro 3'!F28) | G28: =IF('cuadro 1'!G28+'cuadro 2'!G28+'cuadro 3'!G28=0,"",'cuadro 1'!G28+'cuadro 2'!G28+'cuadro 3'!G28) | H28: =IF('cuadro 1'!H28+'cuadro 2'!H28+'cuadro 3'!H28=0,"",'cuadro 1'!H28+'cuadro 2'!H28+'cuadro 3'!H28) | I28: =IF('cuadro 1'!I28+'cuadro 2'!I28+'cuadro 3'!I28=0,"",'cuadro 1'!I28+'cuadro 2'!I28+'cuadro 3'!I28) | J28: =IF('cuadro 1'!J28+'cuadro 2'!J28+'cuadro 3'!J28=0,"",'cuadro 1'!J28+'cuadro 2'!J28+'cuadro 3'!J28) | ... Q28: =IF('cuadro 1'!Q28+'cuadro 2'!Q28+'cuadro 3'!Q28=0,"",'cuadro 1'!Q28+'cuadro 2'!Q28+'cuadro 3'!Q28)
B29: AAA | C29: =IF('cuadro 1'!C29+'cuadro 2'!C29+'cuadro 3'!C29=0,"",'cuadro 1'!C29+'cuadro 2'!C29+'cuadro 3'!C29) | D29: =IF('cuadro 1'!D29+'cuadro 2'!D29+'cuadro 3'!D29=0,"",'cuadro 1'!D29+'cuadro 2'!D29+'cuadro 3'!D29) | E29: =IF('cuadro 1'!E29+'cuadro 2'!E29+'cuadro 3'!E29=0,"",'cuadro 1'!E29+'cuadro 2'!E29+'cuadro 3'!E29) | F29: =IF('cuadro 1'!F29+'cuadro 2'!F29+'cuadro 3'!F29=0,"",'cuadro 1'!F29+'cuadro 2'!F29+'cuadro 3'!F29) | G29: =IF('cuadro 1'!G29+'cuadro 2'!G29+'cuadro 3'!G29=0,"",'cuadro 1'!G29+'cuadro 2'!G29+'cuadro 3'!G29) | H29: =IF('cuadro 1'!H29+'cuadro 2'!H29+'cuadro 3'!H29=0,"",'cuadro 1'!H29+'cuadro 2'!H29+'cuadro 3'!H29) | I29: =IF('cuadro 1'!I29+'cuadro 2'!I29+'cuadro 3'!I29=0,"",'cuadro 1'!I29+'cuadro 2'!I29+'cuadro 3'!I29) | J29: =IF('cuadro 1'!J29+'cuadro 2'!J29+'cuadro 3'!J29=0,"",'cuadro 1'!J29+'cuadro 2'!J29+'cuadro 3'!J29) | ... Q29: =IF('cuadro 1'!Q29+'cuadro 2'!Q29+'cuadro 3'!Q29=0,"",'cuadro 1'!Q29+'cuadro 2'!Q29+'cuadro 3'!Q29)
A30: MAKRO | B30: A | C30: =IF('cuadro 1'!C30+'cuadro 2'!C30+'cuadro 3'!C30=0,"",'cuadro 1'!C30+'cuadro 2'!C30+'cuadro 3'!C30) | D30: =IF('cuadro 1'!D30+'cuadro 2'!D30+'cuadro 3'!D30=0,"",'cuadro 1'!D30+'cuadro 2'!D30+'cuadro 3'!D30) | E30: =IF('cuadro 1'!E30+'cuadro 2'!E30+'cuadro 3'!E30=0,"",'cuadro 1'!E30+'cuadro 2'!E30+'cuadro 3'!E30) | F30: =IF('cuadro 1'!F30+'cuadro 2'!F30+'cuadro 3'!F30=0,"",'cuadro 1'!F30+'cuadro 2'!F30+'cuadro 3'!F30) | G30: =IF('cuadro 1'!G30+'cuadro 2'!G30+'cuadro 3'!G30=0,"",'cuadro 1'!G30+'cuadro 2'!G30+'cuadro 3'!G30) | H30: =IF('cuadro 1'!H30+'cuadro 2'!H30+'cuadro 3'!H30=0,"",'cuadro 1'!H30+'cuadro 2'!H30+'cuadro 3'!H30) | I30: =IF('cuadro 1'!I30+'cuadro 2'!I30+'cuadro 3'!I30=0,"",'cuadro 1'!I30+'cuadro 2'!I30+'cuadro 3'!I30) | J30: =IF('cuadro 1'!J30+'cuadro 2'!J30+'cuadro 3'!J30=0,"",'cuadro 1'!J30+'cuadro 2'!J30+'cuadro 3'!J30) | ... Q30: =IF('cuadro 1'!Q30+'cuadro 2'!Q30+'cuadro 3'!Q30=0,"",'cuadro 1'!Q30+'cuadro 2'!Q30+'cuadro 3'!Q30)
B31: AA | C31: =IF('cuadro 1'!C31+'cuadro 2'!C31+'cuadro 3'!C31=0,"",'cuadro 1'!C31+'cuadro 2'!C31+'cuadro 3'!C31) | D31: =IF('cuadro 1'!D31+'cuadro 2'!D31+'cuadro 3'!D31=0,"",'cuadro 1'!D31+'cuadro 2'!D31+'cuadro 3'!D31) | E31: =IF('cuadro 1'!E31+'cuadro 2'!E31+'cuadro 3'!E31=0,"",'cuadro 1'!E31+'cuadro 2'!E31+'cuadro 3'!E31) | F31: =IF('cuadro 1'!F31+'cuadro 2'!F31+'cuadro 3'!F31=0,"",'cuadro 1'!F31+'cuadro 2'!F31+'cuadro 3'!F31) | G31: =IF('cuadro 1'!G31+'cuadro 2'!G31+'cuadro 3'!G31=0,"",'cuadro 1'!G31+'cuadro 2'!G31+'cuadro 3'!G31) | H31: =IF('cuadro 1'!H31+'cuadro 2'!H31+'cuadro 3'!H31=0,"",'cuadro 1'!H31+'cuadro 2'!H31+'cuadro 3'!H31) | I31: =IF('cuadro 1'!I31+'cuadro 2'!I31+'cuadro 3'!I31=0,"",'cuadro 1'!I31+'cuadro 2'!I31+'cuadro 3'!I31) | J31: =IF('cuadro 1'!J31+'cuadro 2'!J31+'cuadro 3'!J31=0,"",'cuadro 1'!J31+'cuadro 2'!J31+'cuadro 3'!J31) | ... Q31: =IF('cuadro 1'!Q31+'cuadro 2'!Q31+'cuadro 3'!Q31=0,"",'cuadro 1'!Q31+'cuadro 2'!Q31+'cuadro 3'!Q31)
B32: AAA | C32: =IF('cuadro 1'!C32+'cuadro 2'!C32+'cuadro 3'!C32=0,"",'cuadro 1'!C32+'cuadro 2'!C32+'cuadro 3'!C32) | D32: =IF('cuadro 1'!D32+'cuadro 2'!D32+'cuadro 3'!D32=0,"",'cuadro 1'!D32+'cuadro 2'!D32+'cuadro 3'!D32) | E32: =IF('cuadro 1'!E32+'cuadro 2'!E32+'cuadro 3'!E32=0,"",'cuadro 1'!E32+'cuadro 2'!E32+'cuadro 3'!E32) | F32: =IF('cuadro 1'!F32+'cuadro 2'!F32+'cuadro 3'!F32=0,"",'cuadro 1'!F32+'cuadro 2'!F32+'cuadro 3'!F32) | G32: =IF('cuadro 1'!G32+'cuadro 2'!G32+'cuadro 3'!G32=0,"",'cuadro 1'!G32+'cuadro 2'!G32+'cuadro 3'!G32) | H32: =IF('cuadro 1'!H32+'cuadro 2'!H32+'cuadro 3'!H32=0,"",'cuadro 1'!H32+'cuadro 2'!H32+'cuadro 3'!H32) | I32: =IF('cuadro 1'!I32+'cuadro 2'!I32+'cuadro 3'!I32=0,"",'cuadro 1'!I32+'cuadro 2'!I32+'cuadro 3'!I32) | J32: =IF('cuadro 1'!J32+'cuadro 2'!J32+'cuadro 3'!J32=0,"",'cuadro 1'!J32+'cuadro 2'!J32+'cuadro 3'!J32) | ... Q32: =IF('cuadro 1'!Q32+'cuadro 2'!Q32+'cuadro 3'!Q32=0,"",'cuadro 1'!Q32+'cuadro 2'!Q32+'cuadro 3'!Q32)
B33: B | C33: =IF('cuadro 1'!C33+'cuadro 2'!C33+'cuadro 3'!C33=0,"",'cuadro 1'!C33+'cuadro 2'!C33+'cuadro 3'!C33) | D33: =IF('cuadro 1'!D33+'cuadro 2'!D33+'cuadro 3'!D33=0,"",'cuadro 1'!D33+'cuadro 2'!D33+'cuadro 3'!D33) | E33: =IF('cuadro 1'!E33+'cuadro 2'!E33+'cuadro 3'!E33=0,"",'cuadro 1'!E33+'cuadro 2'!E33+'cuadro 3'!E33) | F33: =IF('cuadro 1'!F33+'cuadro 2'!F33+'cuadro 3'!F33=0,"",'cuadro 1'!F33+'cuadro 2'!F33+'cuadro 3'!F33) | G33: =IF('cuadro 1'!G33+'cuadro 2'!G33+'cuadro 3'!G33=0,"",'cuadro 1'!G33+'cuadro 2'!G33+'cuadro 3'!G33) | H33: =IF('cuadro 1'!H33+'cuadro 2'!H33+'cuadro 3'!H33=0,"",'cuadro 1'!H33+'cuadro 2'!H33+'cuadro 3'!H33) | I33: =IF('cuadro 1'!I33+'cuadro 2'!I33+'cuadro 3'!I33=0,"",'cuadro 1'!I33+'cuadro 2'!I33+'cuadro 3'!I33) | J33: =IF('cuadro 1'!J33+'cuadro 2'!J33+'cuadro 3'!J33=0,"",'cuadro 1'!J33+'cuadro 2'!J33+'cuadro 3'!J33) | ... Q33: =IF('cuadro 1'!Q33+'cuadro 2'!Q33+'cuadro 3'!Q33=0,"",'cuadro 1'!Q33+'cuadro 2'!Q33+'cuadro 3'!Q33)
A34: ATA | B34: A | C34: =IF('cuadro 1'!C34+'cuadro 2'!C34+'cuadro 3'!C34=0,"",'cuadro 1'!C34+'cuadro 2'!C34+'cuadro 3'!C34) | D34: =IF('cuadro 1'!D34+'cuadro 2'!D34+'cuadro 3'!D34=0,"",'cuadro 1'!D34+'cuadro 2'!D34+'cuadro 3'!D34) | E34: =IF('cuadro 1'!E34+'cuadro 2'!E34+'cuadro 3'!E34=0,"",'cuadro 1'!E34+'cuadro 2'!E34+'cuadro 3'!E34) | F34: =IF('cuadro 1'!F34+'cuadro 2'!F34+'cuadro 3'!F34=0,"",'cuadro 1'!F34+'cuadro 2'!F34+'cuadro 3'!F34) | G34: =IF('cuadro 1'!G34+'cuadro 2'!G34+'cuadro 3'!G34=0,"",'cuadro 1'!G34+'cuadro 2'!G34+'cuadro 3'!G34) | H34: =IF('cuadro 1'!H34+'cuadro 2'!H34+'cuadro 3'!H34=0,"",'cuadro 1'!H34+'cuadro 2'!H34+'cuadro 3'!H34) | I34: =IF('cuadro 1'!I34+'cuadro 2'!I34+'cuadro 3'!I34=0,"",'cuadro 1'!I34+'cuadro 2'!I34+'cuadro 3'!I34) | J34: =IF('cuadro 1'!J34+'cuadro 2'!J34+'cuadro 3'!J34=0,"",'cuadro 1'!J34+'cuadro 2'!J34+'cuadro 3'!J34) | ... Q34: =IF('cuadro 1'!Q34+'cuadro 2'!Q34+'cuadro 3'!Q34=0,"",'cuadro 1'!Q34+'cuadro 2'!Q34+'cuadro 3'!Q34)
B35: AA | C35: =IF('cuadro 1'!C35+'cuadro 2'!C35+'cuadro 3'!C35=0,"",'cuadro 1'!C35+'cuadro 2'!C35+'cuadro 3'!C35) | D35: =IF('cuadro 1'!D35+'cuadro 2'!D35+'cuadro 3'!D35=0,"",'cuadro 1'!D35+'cuadro 2'!D35+'cuadro 3'!D35) | E35: =IF('cuadro 1'!E35+'cuadro 2'!E35+'cuadro 3'!E35=0,"",'cuadro 1'!E35+'cuadro 2'!E35+'cuadro 3'!E35) | F35: =IF('cuadro 1'!F35+'cuadro 2'!F35+'cuadro 3'!F35=0,"",'cuadro 1'!F35+'cuadro 2'!F35+'cuadro 3'!F35) | G35: =IF('cuadro 1'!G35+'cuadro 2'!G35+'cuadro 3'!G35=0,"",'cuadro 1'!G35+'cuadro 2'!G35+'cuadro 3'!G35) | H35: =IF('cuadro 1'!H35+'cuadro 2'!H35+'cuadro 3'!H35=0,"",'cuadro 1'!H35+'cuadro 2'!H35+'cuadro 3'!H35) | I35: =IF('cuadro 1'!I35+'cuadro 2'!I35+'cuadro 3'!I35=0,"",'cuadro 1'!I35+'cuadro 2'!I35+'cuadro 3'!I35) | J35: =IF('cuadro 1'!J35+'cuadro 2'!J35+'cuadro 3'!J35=0,"",'cuadro 1'!J35+'cuadro 2'!J35+'cuadro 3'!J35) | ... Q35: =IF('cuadro 1'!Q35+'cuadro 2'!Q35+'cuadro 3'!Q35=0,"",'cuadro 1'!Q35+'cuadro 2'!Q35+'cuadro 3'!Q35)
B36: AAA | C36: =IF('cuadro 1'!C36+'cuadro 2'!C36+'cuadro 3'!C36=0,"",'cuadro 1'!C36+'cuadro 2'!C36+'cuadro 3'!C36) | D36: =IF('cuadro 1'!D36+'cuadro 2'!D36+'cuadro 3'!D36=0,"",'cuadro 1'!D36+'cuadro 2'!D36+'cuadro 3'!D36) | E36: =IF('cuadro 1'!E36+'cuadro 2'!E36+'cuadro 3'!E36=0,"",'cuadro 1'!E36+'cuadro 2'!E36+'cuadro 3'!E36) | F36: =IF('cuadro 1'!F36+'cuadro 2'!F36+'cuadro 3'!F36=0,"",'cuadro 1'!F36+'cuadro 2'!F36+'cuadro 3'!F36) | G36: =IF('cuadro 1'!G36+'cuadro 2'!G36+'cuadro 3'!G36=0,"",'cuadro 1'!G36+'cuadro 2'!G36+'cuadro 3'!G36) | H36: =IF('cuadro 1'!H36+'cuadro 2'!H36+'cuadro 3'!H36=0,"",'cuadro 1'!H36+'cuadro 2'!H36+'cuadro 3'!H36) | I36: =IF('cuadro 1'!I36+'cuadro 2'!I36+'cuadro 3'!I36=0,"",'cuadro 1'!I36+'cuadro 2'!I36+'cuadro 3'!I36) | J36: =IF('cuadro 1'!J36+'cuadro 2'!J36+'cuadro 3'!J36=0,"",'cuadro 1'!J36+'cuadro 2'!J36+'cuadro 3'!J36) | ... Q36: =IF('cuadro 1'!Q36+'cuadro 2'!Q36+'cuadro 3'!Q36=0,"",'cuadro 1'!Q36+'cuadro 2'!Q36+'cuadro 3'!Q36)
A37: TOTALES | C37: =SUM(C9:C36) -> 23 | D37: =SUM(D9:D36) -> 239 | E37: =SUM(E9:E36) -> 48 | F37: =SUM(F9:F36) -> 0 | G37: =SUM(G9:G36) -> 0 | H37: =SUM(H9:H36) -> 0 | I37: =SUM(I9:I36) -> 32 | J37: =SUM(J9:J36) -> 652 | ... Q37: =SUM(Q9:Q36) -> 0
C38: =SUM(C37:G37) -> 310 | H38: =SUM(H37:K37) -> 684 | L38: =SUM(L37:P37) -> 9157 | Q38: 0
A39: A | C39: =IF('cuadro 1'!C39+'cuadro 2'!C39+'cuadro 3'!C39=0,"",'cuadro 1'!C39+'cuadro 2'!C39+'cuadro 3'!C39) | D39: =IF('cuadro 1'!D39+'cuadro 2'!D39+'cuadro 3'!D39=0,"",'cuadro 1'!D39+'cuadro 2'!D39+'cuadro 3'!D39) | E39: =IF('cuadro 1'!E39+'cuadro 2'!E39+'cuadro 3'!E39=0,"",'cuadro 1'!E39+'cuadro 2'!E39+'cuadro 3'!E39) | F39: =IF('cuadro 1'!F39+'cuadro 2'!F39+'cuadro 3'!F39=0,"",'cuadro 1'!F39+'cuadro 2'!F39+'cuadro 3'!F39) | G39: =IF('cuadro 1'!G39+'cuadro 2'!G39+'cuadro 3'!G39=0,"",'cuadro 1'!G39+'cuadro 2'!G39+'cuadro 3'!G39) | H39: =IF('cuadro 1'!H39+'cuadro 2'!H39+'cuadro 3'!H39=0,"",'cuadro 1'!H39+'cuadro 2'!H39+'cuadro 3'!H39) | I39: =IF('cuadro 1'!I39+'cuadro 2'!I39+'cuadro 3'!I39=0,"",'cuadro 1'!I39+'cuadro 2'!I39+'cuadro 3'!I39) | J39: =IF('cuadro 1'!J39+'cuadro 2'!J39+'cuadro 3'!J39=0,"",'cuadro 1'!J39+'cuadro 2'!J39+'cuadro 3'!J39) | ... Q39: =IF('cuadro 1'!Q39+'cuadro 2'!Q39+'cuadro 3'!Q39=0,"",'cuadro 1'!Q39+'cuadro 2'!Q39+'cuadro 3'!Q39) | R39: =+'cuadro 1'!R39+'cuadro 2'!R39+'cuadro 3'!R39 -> 250320 | S39: =SUM(R39:R43) -> 299416
A40: AA | C40: =IF('cuadro 1'!C40+'cuadro 2'!C40+'cuadro 3'!C40=0,"",'cuadro 1'!C40+'cuadro 2'!C40+'cuadro 3'!C40) -> 138 | D40: =IF('cuadro 1'!D40+'cuadro 2'!D40+'cuadro 3'!D40=0,"",'cuadro 1'!D40+'cuadro 2'!D40+'cuadro 3'!D40) -> 1092 | E40: =IF('cuadro 1'!E40+'cuadro 2'!E40+'cuadro 3'!E40=0,"",'cuadro 1'!E40+'cuadro 2'!E40+'cuadro 3'!E40) | F40: =IF('cuadro 1'!F40+'cuadro 2'!F40+'cuadro 3'!F40=0,"",'cuadro 1'!F40+'cuadro 2'!F40+'cuadro 3'!F40) | G40: =IF('cuadro 1'!G40+'cuadro 2'!G40+'cuadro 3'!G40=0,"",'cuadro 1'!G40+'cuadro 2'!G40+'cuadro 3'!G40) | H40: =IF('cuadro 1'!H40+'cuadro 2'!H40+'cuadro 3'!H40=0,"",'cuadro 1'!H40+'cuadro 2'!H40+'cuadro 3'!H40) | I40: =IF('cuadro 1'!I40+'cuadro 2'!I40+'cuadro 3'!I40=0,"",'cuadro 1'!I40+'cuadro 2'!I40+'cuadro 3'!I40) | J40: =IF('cuadro 1'!J40+'cuadro 2'!J40+'cuadro 3'!J40=0,"",'cuadro 1'!J40+'cuadro 2'!J40+'cuadro 3'!J40) -> 15630 | ... Q40: =IF('cuadro 1'!Q40+'cuadro 2'!Q40+'cuadro 3'!Q40=0,"",'cuadro 1'!Q40+'cuadro 2'!Q40+'cuadro 3'!Q40) | R40: =+'cuadro 1'!R40+'cuadro 2'!R40+'cuadro 3'!R40 -> 28860
A41: AAA | C41: =IF('cuadro 1'!C41+'cuadro 2'!C41+'cuadro 3'!C41=0,"",'cuadro 1'!C41+'cuadro 2'!C41+'cuadro 3'!C41) | D41: =IF('cuadro 1'!D41+'cuadro 2'!D41+'cuadro 3'!D41=0,"",'cuadro 1'!D41+'cuadro 2'!D41+'cuadro 3'!D41) -> 1776 | E41: =IF('cuadro 1'!E41+'cuadro 2'!E41+'cuadro 3'!E41=0,"",'cuadro 1'!E41+'cuadro 2'!E41+'cuadro 3'!E41) -> 720 | F41: =IF('cuadro 1'!F41+'cuadro 2'!F41+'cuadro 3'!F41=0,"",'cuadro 1'!F41+'cuadro 2'!F41+'cuadro 3'!F41) | G41: =IF('cuadro 1'!G41+'cuadro 2'!G41+'cuadro 3'!G41=0,"",'cuadro 1'!G41+'cuadro 2'!G41+'cuadro 3'!G41) | H41: =IF('cuadro 1'!H41+'cuadro 2'!H41+'cuadro 3'!H41=0,"",'cuadro 1'!H41+'cuadro 2'!H41+'cuadro 3'!H41) | I41: =IF('cuadro 1'!I41+'cuadro 2'!I41+'cuadro 3'!I41=0,"",'cuadro 1'!I41+'cuadro 2'!I41+'cuadro 3'!I41) | J41: =IF('cuadro 1'!J41+'cuadro 2'!J41+'cuadro 3'!J41=0,"",'cuadro 1'!J41+'cuadro 2'!J41+'cuadro 3'!J41) -> 3930 | ... Q41: =IF('cuadro 1'!Q41+'cuadro 2'!Q41+'cuadro 3'!Q41=0,"",'cuadro 1'!Q41+'cuadro 2'!Q41+'cuadro 3'!Q41) | R41: =+'cuadro 1'!R41+'cuadro 2'!R41+'cuadro 3'!R41 -> 6426
...

Sheet cuadro 1
C2: PROCESO DE COMERCIALIZACIÓN ORDEN PEDIDO DE HUEVO | R2: CÓDIGO
R3: VERSIÓN
R4: FECHA
R5: PAGINA
A6: CLIENTE: | P6: FECHA DE PEDIDO: | R6: 45218
A7: LOTE | B7: REF. | C7: ESTUCHE | H7: VITAFILM | L7: AMARRADO | Q7: SUELTO | R7: OBSERVACIONES
C8: 6 | D8: 12 | E8: 15 | F8: 20 | G8: 30 | H8: 15 | I8: 20 | J8: 30 | K8: 60 | L8: 15 | M8: 30 | N8: 45 | O8: 60 | P8: 180 | Q8: 1
A9: MARCA ORO | B9: AAAA | I9: =2+30 -> 32
B10: AAA
B11: AA | C11: =12+1+10 -> 23
B12: A
B13: B | M13: 28 | O13: 11
B14: C
A15: PLUS | B15: AAA | D15: =15+18+6+5+14 -> 58 | E15: =10+5+5+6 -> 26 | J15: =15+20+11+6 -> 52
B16: AA | J16: =20+10 -> 30
A17: CAMPESINO | B17: AA
B18: A
A19: KOSHER | B19: AA-A | J19: =10+10+6 -> 26
A20: DHA | B20: AA-A | D20: 3
A21: SELENIO | B21: AA-A | D21: =6+5 -> 11
A22: JUNIOR | B22: A
A23: TAEQ | B23: AA
A24: OXXO | B24: AA
A25: OLIMPICA | B25: A
B26: B
A27: TAT | B27: A
B28: AA
B29: AAA
A30: MAKRO | B30: A
B31: AA
B32: AAA
B33: B
A34: ATA | B34: A
B35: AA
B36: AAA
A37: TOTALES | C37: =SUM(C9:C36) -> 23 | D37: =SUM(D9:D36) -> 72 | E37: =SUM(E9:E36) -> 26 | F37: =SUM(F9:F36) -> 0 | G37: =SUM(G9:G36) -> 0 | H37: =SUM(H9:H36) -> 0 | I37: =SUM(I9:I36) -> 32 | J37: =SUM(J9:J36) -> 108 | ... Q37: =SUM(Q9:Q36) -> 0
C38: =SUM(C37:G37) -> 121 | H38: =SUM(H37:K37) -> 140 | L38: =SUM(L37:P37) -> 39
A39: A | C39: =+C12*C8+C18*C8+C22*C8++C25*C8+C27*C8+C30*C34*C8 -> 0 | D39: =+D12*D8+D18*D8+D22*D8++D25*D8+D27*D8+D30*D34*D8 -> 0 | E39: =+E12*E8+E18*E8+E22*E8++E25*E8+E27*E8+E30*E34*E8 -> 0 | F39: =+F12*F8+F18*F8+F22*F8++F25*F8+F27*F8+F30*F34*F8 -> 0 | G39: =+G12*G8+G18*G8+G22*G8++G25*G8+G27*G8+G30*G34*G8 -> 0 | H39: =+H12*H8+H18*H8+H22*H8++H25*H8+H27*H8+H30*H34*H8 -> 0 | I39: =+I12*I8+I18*I8+I22*I8++I25*I8+I27*I8+I30*I34*I8 -> 0 | J39: =+J12*J8+J18*J8+J22*J8++J25*J8+J27*J8+J30*J34*J8 -> 0 | ... Q39: =+Q12*Q8+Q18*Q8+Q22*Q8++Q25*Q8+Q27*Q8+Q30*Q34*Q8 -> 0 | R39: =SUM(C39:Q39) -> 0 | S39: =SUM(R39:R44) -> 13544
A40: AA | C40: =+C11*C8+C16*C8+C17*C8+C19*C8+C20*C8+C21*C8+C23*C8+C24*C8+C28*C8+C31*C8+C35*C8 -> 138 | D40: =+D11*D8+D16*D8+D17*D8+D19*D8+D20*D8+D21*D8+D23*D8+D24*D8+D28*D8+D31*D8+D35*D8 -> 168 | E40: =+E11*E8+E16*E8+E17*E8+E19*E8+E20*E8+E21*E8+E23*E8+E24*E8+E28*E8+E31*E8+E35*E8 -> 0 | F40: =+F11*F8+F16*F8+F17*F8+F19*F8+F20*F8+F21*F8+F23*F8+F24*F8+F28*F8+F31*F8+F35*F8 -> 0 | G40: =+G11*G8+G16*G8+G17*G8+G19*G8+G20*G8+G21*G8+G23*G8+G24*G8+G28*G8+G31*G8+G35*G8 -> 0 | H40: =+H11*H8+H16*H8+H17*H8+H19*H8+H20*H8+H21*H8+H23*H8+H24*H8+H28*H8+H31*H8+H35*H8 -> 0 | I40: =+I11*I8+I16*I8+I17*I8+I19*I8+I20*I8+I21*I8+I23*I8+I24*I8+I28*I8+I31*I8+I35*I8 -> 0 | J40: =+J11*J8+J16*J8+J17*J8+J19*J8+J20*J8+J21*J8+J23*J8+J24*J8+J28*J8+J31*J8+J35*J8 -> 1680 | ... Q40: =+Q11*Q8+Q16*Q8+Q17*Q8+Q19*Q8+Q20*Q8+Q21*Q8+Q23*Q8+Q24*Q8+Q28*Q8+Q31*Q8+Q35*Q8 -> 0 | R40: =SUM(C40:Q40) -> 1986
A41: AAA | C41: =+C10*C8+C15*C8+C29*C8+C32*C8+C36*C8 -> 0 | D41: =+D10*D8+D15*D8+D29*D8+D32*D8+D36*D8 -> 696 | E41: =+E10*E8+E15*E8+E29*E8+E32*E8+E36*E8 -> 390 | F41: =+F10*F8+F15*F8+F29*F8+F32*F8+F36*F8 -> 0 | G41: =+G10*G8+G15*G8+G29*G8+G32*G8+G36*G8 -> 0 | H41: =+H10*H8+H15*H8+H29*H8+H32*H8+H36*H8 -> 0 | I41: =+I10*I8+I15*I8+I29*I8+I32*I8+I36*I8 -> 0 | J41: =+J10*J8+J15*J8+J29*J8+J32*J8+J36*J8 -> 1560 | ... Q41: =+Q10*Q8+Q15*Q8+Q29*Q8+Q32*Q8+Q36*Q8 -> 0 | R41: =SUM(C41:Q41) -> 2646
...

Sheet cuadro 2
C2: PROCESO DE COMERCIALIZACIÓN ORDEN PEDIDO DE HUEVO | R2: CÓDIGO
R3: VERSIÓN
R4: FECHA
R5: PAGINA
A6: CLIENTE: | P6: FECHA DE PEDIDO: | R6: 45218
A7: LOTE | B7: REF. | C7: ESTUCHE | H7: VITAFILM | L7: AMARRADO | Q7: SUELTO | R7: OBSERVACIONES
C8: 6 | D8: 12 | E8: 15 | F8: 20 | G8: 30 | H8: 15 | I8: 20 | J8: 30 | K8: 60 | L8: 15 | M8: 30 | N8: 45 | O8: 60 | P8: 180 | Q8: 1
A9: MARCA ORO | B9: AAAA
B10: AAA
B11: AA
B12: A | M12: =4032+4032 -> 8064
B13: B
B14: C
A15: PLUS | B15: AAA
B16: AA
A17: CAMPESINO | B17: AA
B18: A
A19: KOSHER | B19: AA-A
A20: DHA | B20: AA-A
A21: SELENIO | B21: AA-A
A22: JUNIOR | B22: A
A23: TAEQ | B23: AA
A24: OXXO | B24: AA
A25: OLIMPICA | B25: A
B26: B
A27: TAT | B27: A
B28: AA
B29: AAA
A30: MAKRO | B30: A
B31: AA
B32: AAA
B33: B
A34: ATA | B34: A
B35: AA
B36: AAA
A37: TOTALES | C37: =SUM(C9:C36) -> 0 | D37: =SUM(D9:D36) -> 0 | E37: =SUM(E9:E36) -> 0 | F37: =SUM(F9:F36) -> 0 | G37: =SUM(G9:G36) -> 0 | H37: =SUM(H9:H36) -> 0 | I37: =SUM(I9:I36) -> 0 | J37: =SUM(J9:J36) -> 0 | ... Q37: =SUM(Q9:Q36) -> 0
C38: =SUM(C37:G37) -> 0 | H38: =SUM(H37:K37) -> 0 | L38: =SUM(L37:P37) -> 8064
A39: A | C39: =+C12*C8+C18*C8+C22*C8++C25*C8+C27*C8+C30*C34*C8 -> 0 | D39: =+D12*D8+D18*D8+D22*D8++D25*D8+D27*D8+D30*D34*D8 -> 0 | E39: =+E12*E8+E18*E8+E22*E8++E25*E8+E27*E8+E30*E34*E8 -> 0 | F39: =+F12*F8+F18*F8+F22*F8++F25*F8+F27*F8+F30*F34*F8 -> 0 | G39: =+G12*G8+G18*G8+G22*G8++G25*G8+G27*G8+G30*G34*G8 -> 0 | H39: =+H12*H8+H18*H8+H22*H8++H25*H8+H27*H8+H30*H34*H8 -> 0 | I39: =+I12*I8+I18*I8+I22*I8++I25*I8+I27*I8+I30*I34*I8 -> 0 | J39: =+J12*J8+J18*J8+J22*J8++J25*J8+J27*J8+J30*J34*J8 -> 0 | ... Q39: =+Q12*Q8+Q18*Q8+Q22*Q8++Q25*Q8+Q27*Q8+Q30*Q34*Q8 -> 0 | R39: =SUM(C39:Q39) -> 241920 | S39: =SUM(R39:R44) -> 483840
A40: AA | C40: =+C11*C8+C16*C8+C17*C8+C19*C8+C20*C8+C21*C8+C23*C8+C24*C8+C28*C8+C31*C8+C35*C8 -> 0 | D40: =+D11*D8+D16*D8+D17*D8+D19*D8+D20*D8+D21*D8+D23*D8+D24*D8+D28*D8+D31*D8+D35*D8 -> 0 | E40: =+E11*E8+E16*E8+E17*E8+E19*E8+E20*E8+E21*E8+E23*E8+E24*E8+E28*E8+E31*E8+E35*E8 -> 0 | F40: =+F11*F8+F16*F8+F17*F8+F19*F8+F20*F8+F21*F8+F23*F8+F24*F8+F28*F8+F31*F8+F35*F8 -> 0 | G40: =+G11*G8+G16*G8+G17*G8+G19*G8+G20*G8+G21*G8+G23*G8+G24*G8+G28*G8+G31*G8+G35*G8 -> 0 | H40: =+H11*H8+H16*H8+H17*H8+H19*H8+H20*H8+H21*H8+H23*H8+H24*H8+H28*H8+H31*H8+H35*H8 -> 0 | I40: =+I11*I8+I16*I8+I17*I8+I19*I8+I20*I8+I21*I8+I23*I8+I24*I8+I28*I8+I31*I8+I35*I8 -> 0 | J40: =+J11*J8+J16*J8+J17*J8+J19*J8+J20*J8+J21*J8+J23*J8+J24*J8+J28*J8+J31*J8+J35*J8 -> 0 | ... Q40: =+Q11*Q8+Q16*Q8+Q17*Q8+Q19*Q8+Q20*Q8+Q21*Q8+Q23*Q8+Q24*Q8+Q28*Q8+Q31*Q8+Q35*Q8 -> 0 | R40: =SUM(C40:Q40) -> 0
A41: AAA | C41: =+C10*C8+C15*C8+C29*C8+C32*C8+C36*C8 -> 0 | D41: =+D10*D8+D15*D8+D29*D8+D32*D8+D36*D8 -> 0 | E41: =+E10*E8+E15*E8+E29*E8+E32*E8+E36*E8 -> 0 | F41: =+F10*F8+F15*F8+F29*F8+F32*F8+F36*F8 -> 0 | G41: =+G10*G8+G15*G8+G29*G8+G32*G8+G36*G8 -> 0 | H41: =+H10*H8+H15*H8+H29*H8+H32*H8+H36*H8 -> 0 | I41: =+I10*I8+I15*I8+I29*I8+I32*I8+I36*I8 -> 0 | J41: =+J10*J8+J15*J8+J29*J8+J32*J8+J36*J8 -> 0 | ... Q41: =+Q10*Q8+Q15*Q8+Q29*Q8+Q32*Q8+Q36*Q8 -> 0 | R41: =SUM(C41:Q41) -> 0
...

Sheet cuadro 3
C2: PROCESO DE COMERCIALIZACIÓN ORDEN PEDIDO DE HUEVO | R2: CÓDIGO
R3: VERSIÓN
R4: FECHA
R5: PAGINA
A6: CLIENTE: | P6: FECHA DE PEDIDO: | R6: 45218
A7: LOTE | B7: REF. | C7: ESTUCHE | H7: VITAFILM | L7: AMARRADO | Q7: SUELTO | R7: OBSERVACIONES
C8: 6 | D8: 12 | E8: 15 | F8: 20 | G8: 30 | H8: 15 | I8: 20 | J8: 30 | K8: 60 | L8: 15 | M8: 30 | N8: 45 | O8: 60 | P8: 180 | Q8: 1
A9: MARCA ORO | B9: AAAA | C9: 0 | D9: 0 | E9: 0 | F9: 0 | G9: 0 | H9: 0 | I9: 0 | J9: 0 | K9: 0 | L9: 0 | M9: 0 | N9: 0 | O9: 0 | P9: 0
B10: AAA | C10: 0 | D10: 40 | E10: 0 | F10: 0 | G10: 0 | H10: 0 | I10: 0 | J10: 0 | K10: 0 | L10: 0 | M10: 0 | N10: 0 | O10: 0 | P10: 0
B11: AA | C11: 0 | D11: 0 | E11: 0 | F11: 0 | G11: 0 | H11: 0 | I11: 0 | J11: 0 | K11: 0 | L11: 0 | M11: 400 | N11: 0 | O11: 0 | P11: 0
B12: A | C12: 0 | D12: 0 | E12: 0 | F12: 0 | G12: 0 | H12: 0 | I12: 0 | J12: 0 | K12: 0 | L12: 0 | M12: 150 | N12: 0 | O12: 0 | P12: 0
B13: B | C13: 0 | D13: 0 | E13: 0 | F13: 0 | G13: 0 | H13: 0 | I13: 0 | J13: 0 | K13: 0 | L13: 0 | M13: 229 | N13: 0 | O13: 15 | P13: 0
B14: C | C14: 0 | D14: 0 | E14: 0 | F14: 0 | G14: 0 | H14: 0 | I14: 0 | J14: 0 | K14: 0 | L14: 0 | M14: 0 | N14: 0 | O14: 0 | P14: 0
A15: PLUS | B15: AAA | C15: 0 | D15: 50 | E15: 22 | F15: 0 | G15: 0 | H15: 0 | I15: 0 | J15: 79 | K15: 0 | L15: 0 | M15: 0 | N15: 0 | O15: 0 | P15: 0
B16: AA | C16: 0 | D16: 0 | E16: 0 | F16: 0 | G16: 0 | H16: 0 | I16: 0 | J16: 0 | K16: 0 | L16: 0 | M16: 0 | N16: 0 | O16: 0 | P16: 0
A17: CAMPESINO | B17: AA | C17: 0 | D17: 55 | E17: 0 | F17: 0 | G17: 0 | H17: 0 | I17: 0 | J17: 380 | K17: 0 | L17: 0 | M17: 0 | N17: 0 | O17: 0 | P17: 0
B18: A | C18: 0 | D18: 0 | E18: 0 | F18: 0 | G18: 0 | H18: 0 | I18: 0 | J18: 0 | K18: 0 | L18: 0 | M18: 0 | N18: 0 | O18: 0 | P18: 0
A19: KOSHER | B19: AA-A | C19: 0 | D19: 0 | E19: 0 | F19: 0 | G19: 0 | H19: 0 | I19: 0 | J19: 85 | K19: 0 | L19: 0 | M19: 0 | N19: 0 | O19: 0 | P19: 0
A20: DHA | B20: AA-A | C20: 0 | D20: 10 | E20: 0 | F20: 0 | G20: 0 | H20: 0 | I20: 0 | J20: 0 | K20: 0 | L20: 0 | M20: 0 | N20: 0 | O20: 0 | P20: 0
A21: SELENIO | B21: AA-A | C21: 0 | D21: 12 | E21: 0 | F21: 0 | G21: 0 | H21: 0 | I21: 0 | J21: 0 | K21: 0 | L21: 0 | M21: 0 | N21: 0 | O21: 0 | P21: 0
A22: JUNIOR | B22: A | C22: 0 | D22: 0 | E22: 0 | F22: 0 | G22: 0 | H22: 0 | I22: 0 | J22: 0 | K22: 0 | L22: 0 | M22: 0 | N22: 0 | O22: 0 | P22: 0
A23: TAEQ | B23: AA
A24: OXXO | B24: AA
A25: OLIMPICA | B25: A | M25: 130
B26: B | M26: 130
A27: TAT | B27: A
B28: AA
B29: AAA
A30: MAKRO | B30: A
B31: AA
B32: AAA
B33: B
A34: ATA | B34: A
B35: AA
B36: AAA
A37: TOTALES | C37: =SUM(C9:C36) -> 0 | D37: =SUM(D9:D36) -> 167 | E37: =SUM(E9:E36) -> 22 | F37: =SUM(F9:F36) -> 0 | G37: =SUM(G9:G36) -> 0 | H37: =SUM(H9:H36) -> 0 | I37: =SUM(I9:I36) -> 0 | J37: =SUM(J9:J36) -> 544 | ... Q37: =SUM(Q9:Q36) -> 0
C38: =SUM(C37:G37) -> 189 | H38: =SUM(H37:K37) -> 544 | L38: =SUM(L37:P37) -> 1054
A39: A | C39: =+C12*C8+C18*C8+C22*C8++C25*C8+C27*C8+C30*C34*C8 -> 0 | D39: =+D12*D8+D18*D8+D22*D8++D25*D8+D27*D8+D30*D34*D8 -> 0 | E39: =+E12*E8+E18*E8+E22*E8++E25*E8+E27*E8+E30*E34*E8 -> 0 | F39: =+F12*F8+F18*F8+F22*F8++F25*F8+F27*F8+F30*F34*F8 -> 0 | G39: =+G12*G8+G18*G8+G22*G8++G25*G8+G27*G8+G30*G34*G8 -> 0 | H39: =+H12*H8+H18*H8+H22*H8++H25*H8+H27*H8+H30*H34*H8 -> 0 | I39: =+I12*I8+I18*I8+I22*I8++I25*I8+I27*I8+I30*I34*I8 -> 0 | J39: =+J12*J8+J18*J8+J22*J8++J25*J8+J27*J8+J30*J34*J8 -> 0 | ... Q39: =+Q12*Q8+Q18*Q8+Q22*Q8++Q25*Q8+Q27*Q8+Q30*Q34*Q8 -> 0 | R39: =SUM(C39:Q39) -> 8400 | S39: =SUM(R39:R44) -> 101448
A40: AA | C40: =+C11*C8+C16*C8+C17*C8+C19*C8+C20*C8+C21*C8+C23*C8+C24*C8+C28*C8+C31*C8+C35*C8 -> 0 | D40: =+D11*D8+D16*D8+D17*D8+D19*D8+D20*D8+D21*D8+D23*D8+D24*D8+D28*D8+D31*D8+D35*D8 -> 924 | E40: =+E11*E8+E16*E8+E17*E8+E19*E8+E20*E8+E21*E8+E23*E8+E24*E8+E28*E8+E31*E8+E35*E8 -> 0 | F40: =+F11*F8+F16*F8+F17*F8+F19*F8+F20*F8+F21*F8+F23*F8+F24*F8+F28*F8+F31*F8+F35*F8 -> 0 | G40: =+G11*G8+G16*G8+G17*G8+G19*G8+G20*G8+G21*G8+G23*G8+G24*G8+G28*G8+G31*G8+G35*G8 -> 0 | H40: =+H11*H8+H16*H8+H17*H8+H19*H8+H20*H8+H21*H8+H23*H8+H24*H8+H28*H8+H31*H8+H35*H8 -> 0 | I40: =+I11*I8+I16*I8+I17*I8+I19*I8+I20*I8+I21*I8+I23*I8+I24*I8+I28*I8+I31*I8+I35*I8 -> 0 | J40: =+J11*J8+J16*J8+J17*J8+J19*J8+J20*J8+J21*J8+J23*J8+J24*J8+J28*J8+J31*J8+J35*J8 -> 13950 | ... Q40: =+Q11*Q8+Q16*Q8+Q17*Q8+Q19*Q8+Q20*Q8+Q21*Q8+Q23*Q8+Q24*Q8+Q28*Q8+Q31*Q8+Q35*Q8 -> 0 | R40: =SUM(C40:Q40) -> 26874
A41: AAA | C41: =+C10*C8+C15*C8+C29*C8+C32*C8+C36*C8 -> 0 | D41: =+D10*D8+D15*D8+D29*D8+D32*D8+D36*D8 -> 1080 | E41: =+E10*E8+E15*E8+E29*E8+E32*E8+E36*E8 -> 330 | F41: =+F10*F8+F15*F8+F29*F8+F32*F8+F36*F8 -> 0 | G41: =+G10*G8+G15*G8+G29*G8+G32*G8+G36*G8 -> 0 | H41: =+H10*H8+H15*H8+H29*H8+H32*H8+H36*H8 -> 0 | I41: =+I10*I8+I15*I8+I29*I8+I32*I8+I36*I8 -> 0 | J41: =+J10*J8+J15*J8+J29*J8+J32*J8+J36*J8 -> 2370 | ... Q41: =+Q10*Q8+Q15*Q8+Q29*Q8+Q32*Q8+Q36*Q8 -> 0 | R41: =SUM(C41:Q41) -> 3780
...

Sheet NOTIFICACION
J3: FECHA
C4: MATERIAL | D4: REFERENCIA | E4: NECESIDAD BANDEJA | F4: NECESIDAD UNIDADES | G4: FISICO BANDEJAS | H4: FISICO UNIDADES | I4: PRODUCIR BANDEJAS | J4: PRODUCIR UNIDADES | K4: NOTIFICADO | L4: PRODUCCION | M4: NOTIFICAR | N4: PRODUCCION | O4: NOTIFICAR
C5: 30018 | D5: CAMPESINO TERMO ORO AAx30 | E5: =+RESUMEN!J17 -> 380 | F5: =+E5*30 -> 11400 | G5: =+H5/30 -> 0 | H5: =VLOOKUP(C$5:C$35,'INVENTARIO FISICO'!A$1:B$38,2,FALSE) -> 0 | I5: =+E5-G5 -> 380 | J5: =+F5-H5 -> 11400 | K5: =IF(J5<0,"0",J5*1) -> 11400
C6: 30019 | D6: CAMPESINO X12 | E6: =+RESUMEN!D17 -> 55 | F6: =+E6*12 -> 660 | G6: =+H6/12 -> 0 | H6: =VLOOKUP(C$5:C$35,'INVENTARIO FISICO'!A$1:B$38,2,FALSE) -> 0 | I6: =+E6-G6 -> 55 | J6: =+F6-H6 -> 660 | K6: =IF(J6<0,"0",J6*1) -> 660
C7: 30024 | D7: JUNIOR X 30 | E7: =+RESUMEN!J22 | F7: =+E7*30 -> #VALUE! | G7: =+H7/30 -> 0 | H7: =VLOOKUP(C$5:C$35,'INVENTARIO FISICO'!A$1:B$38,2,FALSE) -> 0 | I7: =+E7-G7 -> #VALUE! | J7: =+F7-H7 -> #VALUE! | K7: =IF(J7<0,"0",J7*1) -> #VALUE!
C8: 30031 | D8: HUEVO ORO TIPO A X 30 TERMO | E8: =+RESUMEN!J12 | F8: =+E8*30 -> #VALUE! | G8: =+H8/30 -> 0 | H8: =VLOOKUP(C$5:C$35,'INVENTARIO FISICO'!A$1:B$38,2,FALSE) -> 0 | I8: =+E8-G8 -> #VALUE! | J8: =+F8-H8 -> #VALUE! | K8: =IF(J8<0,"0",J8*1) -> #VALUE!
C9: 30032 | D9: HUEVO ORO SELENIO X 12 UND | E9: =+RESUMEN!D21 -> 23 | F9: =+E9*12 -> 276 | G9: =+H9/12 -> 0 | H9: =VLOOKUP(C$5:C$35,'INVENTARIO FISICO'!A$1:B$38,2,FALSE) -> 0 | I9: =+E9-G9 -> 23 | J9: =+F9-H9 -> 276 | K9: =IF(J9<0,"0",J9*1) -> 276
C10: 30037 | D10: HUEVOS ORO A X 12 ESTUCHE | E10: =+RESUMEN!D12 | F10: =+E10*12 -> #VALUE! | G10: =+H10/12 -> 0 | H10: =VLOOKUP(C$5:C$35,'INVENTARIO FISICO'!A$1:B$38,2,FALSE) -> 0 | I10: =+E10-G10 -> #VALUE! | J10: =+F10-H10 -> #VALUE! | K10: =IF(J10<0,"0",J10*1) -> #VALUE!
C11: 30040 | D11: HUEVOS ORO A X 30 AMARRADO | E11: =+'cuadro 1'!M12+'cuadro 1'!M27+'cuadro 2'!M12+'cuadro 2'!M27+'cuadro 3'!M12+'cuadro 3'!M27 -> 8214 | F11: =+E11*30 -> 246420 | G11: =+H11/30 -> 0 | H11: =VLOOKUP(C$5:C$35,'INVENTARIO FISICO'!A$1:B$38,2,FALSE) -> 0 | I11: =+E11-G11 -> 8214 | J11: =+F11-H11 -> 246420 | K11: =IF(J11<0,"0",J11*1) -> 246420
C12: 30041 | D12: HUEVOS ORO A X 6 ESTUCHE | E12: =+RESUMEN!C12 | F12: =+E12*6 -> #VALUE! | G12: =+H12/6 -> 0 | H12: =VLOOKUP(C$5:C$35,'INVENTARIO FISICO'!A$1:B$38,2,FALSE) -> 0 | I12: =+E12-G12 -> #VALUE! | J12: =+F12-H12 -> #VALUE! | K12: =IF(J12<0,"0",J12*1) -> #VALUE!
C13: 30043 | D13: HUEVOS ORO AA X 12 ESTUCHE | E13: =+RESUMEN!D11 | F13: =+E13*12 -> #VALUE! | G13: =+H13/12 -> 0 | H13: =VLOOKUP(C$5:C$35,'INVENTARIO FISICO'!A$1:B$38,2,FALSE) -> 0 | I13: =+E13-G13 -> #VALUE! | J13: =+F13-H13 -> #VALUE! | K13: =IF(J13<0,"0",J13*1) -> #VALUE!
C14: 30045 | D14: HUEVOS ORO AA X 15 TERMO | E14: =+RESUMEN!H24 | F14: =+E14*15 -> #VALUE! | G14: =+H14/15 -> 0 | H14: =VLOOKUP(C$5:C$35,'INVENTARIO FISICO'!A$1:B$38,2,FALSE) -> 0 | I14: =+E14-G14 -> #VALUE! | J14: =+F14-H14 -> #VALUE! | K14: =IF(J14<0,"0",J14*1) -> #VALUE!
C15: 30046 | D15: HUEVOS ORO AA X 30 AMARRADO | E15: =+'cuadro 1'!M11+'cuadro 1'!M28+'cuadro 2'!M11+'cuadro 2'!M28+'cuadro 3'!M11+'cuadro 3'!M28 -> 400 | F15: =+E15*30 -> 12000 | G15: =+H1530 -> 0 | H15: =VLOOKUP(C$5:C$35,'INVENTARIO FISICO'!A$1:B$38,2,FALSE) -> 0 | I15: =+E15-G15 -> 400 | J15: =+F15-H15 -> 12000 | K15: =IF(J15<0,"0",J15*1) -> 12000
C16: 30047 | D16: HUEVOS ORO AA X 30 TERMO | E16: =+'cuadro 1'!J11+'cuadro 1'!J24+'cuadro 2'!J11+'cuadro 2'!J24+'cuadro 3'!J11+'cuadro 3'!J24 -> 0 | F16: =+E16*30 -> 0 | G16: =+H16/30 -> 0 | H16: =VLOOKUP(C$5:C$35,'INVENTARIO FISICO'!A$1:B$38,2,FALSE) -> 0 | I16: =+E16-G16 -> 0 | J16: =+F16-H16 -> 0 | K16: =IF(J16<0,"0",J16*1) -> 0
C17: 30048 | D17: HUEVOS ORO AA X 6 ESTUCHE | E17: =+RESUMEN!C11 -> 23 | F17: =+E17*6 -> 138 | G17: =+H17/6 -> 0 | H17: =VLOOKUP(C$5:C$35,'INVENTARIO FISICO'!A$1:B$38,2,FALSE) -> 0 | I17: =+E17-G17 -> 23 | J17: =+F17-H17 -> 138 | K17: =IF(J17<0,"0",J17*1) -> 138
C18: 30049 | D18: HUEVOS ORO AAA X 12 ESTUCHE | E18: =+RESUMEN!D10 -> 40 | F18: =+E18*12 -> 480 | G18: =+H18/12 -> 0 | H18: =VLOOKUP(C$5:C$35,'INVENTARIO FISICO'!A$1:B$38,2,FALSE) -> 0 | I18: =+E18-G18 -> 40 | J18: =+F18-H18 -> 480 | K18: =IF(J18<0,"0",J18*1) -> 480
C19: 30052 | D19: HUEVOS ORO AAA X 30 AMARRADO | E19: =+'cuadro 1'!M10+'cuadro 1'!M29+'cuadro 2'!M10+'cuadro 2'!M29+'cuadro 3'!M10+'cuadro 3'!M29 -> 0 | F19: =+E19*30 -> 0 | G19: =+H19/30 -> 0 | H19: =VLOOKUP(C$5:C$35,'INVENTARIO FISICO'!A$1:B$38,2,FALSE) -> 0 | I19: =+E19-G19 -> 0 | J19: =+F19-H19 -> 0 | K19: =IF(J19<0,"0",J19*1) -> 0
C20: 30056 | D20: HUEVOS ORO B X 30 AMARRADO | E20: =+RESUMEN!M13 -> 257 | F20: =+E20*30 -> 7710 | G20: =+H20/30 -> 0 | H20: =VLOOKUP(C$5:C$35,'INVENTARIO FISICO'!A$1:B$38,2,FALSE) -> 0 | I20: =+E20-G20 -> 257 | J20: =+F20-H20 -> 7710 | K20: =IF(J20<0,"0",J20*1) -> 7710
C21: 40105 | D21: CAMPESINO TERMO ORO X 15 | E21: =+RESUMEN!H17 | F21: =+E21*15 -> #VALUE! | G21: =+H21/15 -> 0 | H21: =VLOOKUP(C$5:C$35,'INVENTARIO FISICO'!A$1:B$38,2,FALSE) -> 0 | I21: =+E21-G21 -> #VALUE! | J21: =+F21-H21 -> #VALUE! | K21: =IF(J21<0,"0",J21*1) -> #VALUE!
C22: 40135 | D22: HUEVO ORO KOSHER X 12 UND | E22: =+RESUMEN!D19 | F22: =+E22*12 -> #VALUE! | G22: =+H22/12 -> 0 | H22: =VLOOKUP(C$5:C$35,'INVENTARIO FISICO'!A$1:B$38,2,FALSE) -> 0 | I22: =+E22-G22 -> #VALUE! | J22: =+F22-H22 -> #VALUE! | K22: =IF(J22<0,"0",J22*1) -> #VALUE!
C23: 40205 | D23: HUEVOS ORO PLUS X 20 | E23: =+RESUMEN!I9 -> 32 | F23: =+E23*20 -> 640 | G23: =+H23/20 -> 0 | H23: =VLOOKUP(C$5:C$35,'INVENTARIO FISICO'!A$1:B$38,2,FALSE) -> 0 | I23: =+E23-G23 -> 32 | J23: =+F23-H23 -> 640 | K23: =IF(J23<0,"0",J23*1) -> 640
C24: 40254 | D24: HUEVOS ORO DHA X 12 UND | E24: =+RESUMEN!D20 -> 13 | F24: =+E24*12 -> 156 | G24: =+H24/12 -> 0 | H24: =VLOOKUP(C$5:C$35,'INVENTARIO FISICO'!A$1:B$38,2,FALSE) -> 0 | I24: =+E24-G24 -> 13 | J24: =+F24-H24 -> 156 | K24: =IF(J24<0,"0",J24*1) -> 156
C25: 40265 | D25: HUEVOS ORO PLUS AAA X 30 | E25: =+RESUMEN!J15 -> 131 | F25: =+E25*30 -> 3930 | G25: =+H25/30 -> 0 | H25: =VLOOKUP(C$5:C$35,'INVENTARIO FISICO'!A$1:B$38,2,FALSE) -> 0 | I25: =+E25-G25 -> 131 | J25: =+F25-H25 -> 3930 | K25: =IF(J25<0,"0",J25*1) -> 3930
C26: 40434 | D26: HUEVOS ORO B X 60 AMARRADO | E26: =+RESUMEN!O13 -> 26 | F26: =+E26*60 -> 1560 | G26: =+H26/30 -> 0 | H26: =VLOOKUP(C$5:C$35,'INVENTARIO FISICO'!A$1:B$38,2,FALSE) -> 0 | I26: =+E26-G26 -> 26 | J26: =+F26-H26 -> 1560 | K26: =IF(J26<0,"0",J26*1) -> 1560
C27: 40475 | D27: HUEVOS PLUS AAA X 12 ESTUCHE | E27: =+RESUMEN!D15 -> 108 | F27: =+E27*12 -> 1296 | G27: =+H27/12 -> 0 | H27: =VLOOKUP(C$5:C$35,'INVENTARIO FISICO'!A$1:B$38,2,FALSE) -> 0 | I27: =+E27-G27 -> 108 | J27: =+F27-H27 -> 1296 | K27: =IF(J27<0,"0",J27*1) -> 1296
C28: 40477 | D28: HUEVOS ORO PLUS AAA X 15 | E28: =+RESUMEN!E15 -> 48 | F28: =+E28*15 -> 720 | G28: =+H28/15 -> 0 | H28: =VLOOKUP(C$5:C$35,'INVENTARIO FISICO'!A$1:B$38,2,FALSE) -> 0 | I28: =+E28-G28 -> 48 | J28: =+F28-H28 -> 720 | K28: =IF(J28<0,"0",J28*1) -> 720
C29: 40515 | D29: TAEQ AA X 15 ESTUCHE | E29: =+RESUMEN!E23 | F29: =+E29*15 -> #VALUE! | G29: =+H29/15 -> 0 | H29: =VLOOKUP(C$5:C$35,'INVENTARIO FISICO'!A$1:B$38,2,FALSE) -> 0 | I29: =+E29-G29 -> #VALUE! | J29: =+F29-H29 -> #VALUE! | K29: =IF(J29<0,"0",J29*1) -> #VALUE!
C30: 40526 | D30: HUEVO ORO KOSHER X 30 UND | E30: =+RESUMEN!J19 -> 111 | F30: =+E30*30 -> 3330 | G30: =+H30/30 -> 0 | H30: =VLOOKUP(C$5:C$35,'INVENTARIO FISICO'!A$1:B$38,2,FALSE) -> 0 | I30: =+E30-G30 -> 111 | J30: =+F30-H30 -> 3330 | K30: =IF(J30<0,"0",J30*1) -> 3330
C31: 40537 | D31: HUEVOS ORO PLUS AA X 30 | E31: =+RESUMEN!J16 -> 30 | F31: =+E31*30 -> 900 | G31: =+H31/30 -> 0 | H31: =VLOOKUP(C$5:C$35,'INVENTARIO FISICO'!A$1:B$38,2,FALSE) -> 0 | I31: =+E31-G31 -> 30 | J31: =+F31-H31 -> 900 | K31: =IF(J31<0,"0",J31*1) -> 900
C32: 40538 | D32: HUEVOS AA PLUS CRISTAL X 15 | E32: =+RESUMEN!E16 | F32: =+E32*15 -> #VALUE! | G32: =+H32/15 -> 0 | H32: =VLOOKUP(C$5:C$35,'INVENTARIO FISICO'!A$1:B$38,2,FALSE) -> 0 | I32: =+E32-G32 -> #VALUE! | J32: =+F32-H32 -> #VALUE! | K32: =IF(J32<0,"0",J32*1) -> #VALUE!
C33: 40668 | D33: CAMPESINO TERMO ORO A X 30 | E33: =+RESUMEN!J18 | F33: =+E33*30 -> #VALUE! | G33: =+H33/30 -> 0 | H33: =VLOOKUP(C$5:C$35,'INVENTARIO FISICO'!A$1:B$38,2,FALSE) -> 0 | I33: =+E33-G33 -> #VALUE! | J33: =+F33-H33 -> #VALUE! | K33: =IF(J33<0,"0",J33*1) -> #VALUE!
C34: 40789 | D34: A X 30 AMARRADO OLIMPICA | E34: =+RESUMEN!M25 -> 130 | F34: =+E34*30 -> 3900 | G34: =+H34/30 -> 0 | H34: =VLOOKUP(C$5:C$35,'INVENTARIO FISICO'!A$1:B$38,2,FALSE) -> 0 | I34: =+E34-G34 -> 130 | J34: =+F34-H34 -> 3900 | K34: =IF(J34<0,"0",J34*1) -> 3900
C35: 40790 | D35: B X 30 AMARRADO OLIMPICA | E35: =+RESUMEN!M26 -> 130 | F35: =+E35*30 -> 3900 | G35: =+H35/30 -> 0 | H35: =VLOOKUP(C$5:C$35,'INVENTARIO FISICO'!A$1:B$38,2,FALSE) -> 0 | I35: =+E35-G35 -> 130 | J35: =+F35-H35 -> 3900 | K35: =IF(J35<0,"0",J35*1) -> 3900
C36: 40803 | D36: HUEVOS ORO PLUS AA X 18 | E36: =+RESUMEN!F16 | F36: =+E36*30 -> #VALUE! | G36: =+H36/30 -> 0 | H36: =VLOOKUP(C$5:C$41,'INVENTARIO FISICO'!A$1:B$38,2,FALSE) -> 0 | I36: =+E36-G36 -> #VALUE! | J36: =+F36-H36 -> #VALUE! | K36: =IF(J36<0,"0",J36*1) -> #VALUE!
C37: 40829 | D37: A ROJO AMARRADO X 60 M&C O | E37: =+RESUMEN!O30 | F37: =+E37*60 -> #VALUE! | G37: =+H37/60 -> 0 | H37: =VLOOKUP(C$5:C$41,'INVENTARIO FISICO'!A$1:B$38,2,FALSE) -> 0 | I37: =+E37-G37 -> #VALUE! | J37: =+F37-H37 -> #VALUE! | K37: =IF(J37<0,"0",J37*1) -> #VALUE!
C38: 40830 | D38: A ROJO X 30 AMARRADO M&C O | E38: =+RESUMEN!M30 | F38: =+E38*30 -> #VALUE! | G38: =+H38/30 -> 0 | H38: =VLOOKUP(C$5:C$41,'INVENTARIO FISICO'!A$1:B$38,2,FALSE) -> 0 | I38: =+E38-G38 -> #VALUE! | J38: =+F38-H38 -> #VALUE! | K38: =IF(J38<0,"0",J38*1) -> #VALUE!
C39: 40831 | D39: AA ROJO X 30 AMARRADO ARO O | E39: =+RESUMEN!M31 | F39: =+E39*30 -> #VALUE! | G39: =+H39/30 -> 0 | H39: =VLOOKUP(C$5:C$41,'INVENTARIO FISICO'!A$1:B$38,2,FALSE) -> 0 | I39: =+E39-G39 -> #VALUE! | J39: =+F39-H39 -> #VALUE! | K39: =IF(J39<0,"0",J39*1) -> #VALUE!
C40: 40832 | D40: B ROJO X 30 AMARRADO M&C O | E40: =+RESUMEN!M33 | F40: =+E40*30 -> #VALUE! | G40: =+H40/30 -> 0 | H40: =VLOOKUP(C$5:C$41,'INVENTARIO FISICO'!A$1:B$38,2,FALSE) -> 0 | I40: =+E40-G40 -> #VALUE! | J40: =+F40-H40 -> #VALUE! | K40: =IF(J40<0,"0",J40*1) -> #VALUE!
C41: 40833 | D41: AAA ROJO TRMFO ARO X 30UND O | E41: =+RESUMEN!J32 | F41: =+E41*30 -> #VALUE! | G41: =+H41/30 -> 0 | H41: =VLOOKUP(C$5:C$41,'INVENTARIO FISICO'!A$1:B$38,2,FALSE) -> 0 | I41: =+E41-G41 -> #VALUE! | J41: =+F41-H41 -> #VALUE! | K41: =IF(J41<0,"0",J41*1) -> #VALUE!

Sheet INVENTARIO FISICO
A1: MATERIAL | B1: CANTIDAD
A2: 30018
A3: 30019
A4: 30024
A5: 30031
A6: 30032
A7: 30037
A8: 30040
A9: 30041
A10: 30043
A11: 30045
A12: 30046
A13: 30047
... A38: 40833

Sheet CONSUMO MATERIAL DE EMPAQUE
C4: MATERIAL | D4: REFERENCIA | E4: SOLAPA | F4: ANILLO | G4: COLLARIN | H4: CENEFA | I4: SEPARADOR CAJA | J4: LAMINA | K4: CAJA
C5: 30018 | D5: CAMPESINO TERMOENCOGIDO ORO X 30 | E5: =+NOTIFICACION!E5/30 -> 12.666667 | I5: =E5/10 -> 1.2666667 | K5: =E5/10 -> 1.2666667
C6: 30019 | D6: CAMPESINO X12 | F6: =+NOTIFICACION!E6/12 -> 4.5833333 | K6: =F6/24 -> 0.19097222
C7: 30024 | D7: JUNIOR X 30 | E7: =+NOTIFICACION!E7/30 -> #VALUE! | I7: =E7/10 -> #VALUE! | K7: =E7/10 -> #VALUE!
C8: 30031 | D8: HUEVO ORO ROJO TIPO A X 30 TERMOENCOGIDO | H8: =+NOTIFICACION!E8/30 -> #VALUE! | I8: =H8/10 -> #VALUE! | K8: =H8/10 -> #VALUE!
C9: 30032 | D9: HUEVO ORO SELENIO ORGANICO X 12 UND | F9: =+NOTIFICACION!E9/12 -> 1.9166667 | K9: =F9/24 -> 0.079861111
C10: 30037 | D10: HUEVOS ORO A X 12 ESTUCHE | F10: =+NOTIFICACION!E10/12 -> #VALUE! | K10: =F10/24 -> #VALUE!
C11: 30040 | D11: HUEVOS ORO A X 30 AMARRADO | G11: =+NOTIFICACION!E11/30 -> 273.8 | J11: =G11/168 -> 1.6297619
C12: 30041 | D12: HUEVOS ORO A X 6 ESTUCHE | F12: =+NOTIFICACION!E12/6 -> #VALUE! | K12: =F12/48 -> #VALUE!
C13: 30043 | D13: HUEVOS ORO AA X 12 ESTUCHE | F13: =+NOTIFICACION!E13/12 -> #VALUE! | K13: =F13/24 -> #VALUE!
C14: 30045 | D14: HUEVOS ORO AA X 15 TERMOENCOGIDO | H14: =+NOTIFICACION!E14/15 -> #VALUE! | I14: =H14/24 -> #VALUE! | K14: =H14/24 -> #VALUE!
C15: 30046 | D15: HUEVOS ORO AA X 30 AMARRADO | G15: =+NOTIFICACION!E15/30 -> 13.333333 | J15: =G15/168 -> 0.079365079
C16: 30046 | D16: HUEVOS ORO AA X 30 AMARRADO OXXO | G16: =+NOTIFICACION!J16/30 -> 0 | I16: =G16/12 -> 0 | K16: =G16/12 -> 0
C17: 30047 | D17: HUEVOS ORO AA X 30 TERMOENCOGIDO | H17: =+NOTIFICACION!E17/30 -> 0.76666667 | I17: =H17/10 -> 0.076666667 | K17: =H17/10 -> 0.076666667
C18: 30048 | D18: HUEVOS ORO AA X 6 ESTUCHE | F18: =+NOTIFICACION!E18/6 -> 6.6666667 | K18: =F18/48 -> 0.13888889
C19: 30049 | D19: HUEVOS ORO AAA X 12 ESTUCHE | F19: =+NOTIFICACION!E19/12 -> 0 | K19: =F19/24 -> 0
C20: 30052 | D20: HUEVOS ORO AAA X 30 AMARRADO | G20: =+NOTIFICACION!J20/30 -> 257 | J20: =G20/60 -> 4.2833333
C21: 30056 | D21: HUEVOS ORO B X 30 AMARRADO | G21: =+NOTIFICACION!E21/30 -> #VALUE! | J21: =G21/168 -> #VALUE!
C22: 30060 | D22: HUEVOS ORO ROTO LIMPIO X 30 LBS | E22: =+NOTIFICACION!E22/30 -> #VALUE! | J22: =E22/10 -> #VALUE! | K22: =E22/10 -> #VALUE!
C23: 40105 | D23: CAMPESINO TERMOENCOGIDO ORO X 15 | E23: =+NOTIFICACION!E23/15 -> 2.1333333 | I23: =E23/20 -> 0.10666667 | K23: =E23/20 -> 0.10666667
C24: 40135 | D24: HUEVO ORO KOSHER X 12 UND | F24: =+NOTIFICACION!#REF!/12 -> #REF! | K24: =F24/24 -> #REF!
C25: 40205 | D25: HUEVOS ORO PLUS X 20 | E25: =+NOTIFICACION!#REF!/20 -> #REF! | J25: =E25/8 -> #REF! | K25: =E25/8 -> #REF!
C26: 40254 | D26: HUEVOS ORO DHA X 12 UND | E26: =+NOTIFICACION!#REF!/12 -> #REF! | F26: =+NOTIFICACION!#REF!/12 -> #REF! | K26: =E26/24 -> #REF!
C27: 40265 | D27: HUEVOS ORO PLUS AAA X 30 | E27: =+NOTIFICACION!#REF!/30 -> #REF! | I27: =E27/10 -> #REF! | K27: =E27/10 -> #REF!
C28: 40327 | D28: HUEVOS ORO AA AMARRADO X 60 | E28: =+NOTIFICACION!E24/30 -> 0.43333333 | F28: 0 | G28: 0 | H28: 0 | J28: 0 | K28: 0
C29: 40475 | D29: HUEVOS ORO PLUS AAA X 12 ESTUCHE | F29: =+NOTIFICACION!E25/12 -> 10.916667 | K29: =F29/24 -> 0.45486111
C30: 40477 | D30: HUEVOS ORO PLUS AAA X 15 | F30: =+NOTIFICACION!#REF!/15 -> #REF! | K30: =F30/24 -> #REF!
C31: 40515 | D31: TAEQ AA X 15 ESTUCHE | F31: =+NOTIFICACION!E27/15 -> 7.2 | K31: =F31/24 -> 0.3
C32: 40525 | D32: CAMPESINO TERMOENCOGIDO ORO X 60 | E32: =+NOTIFICACION!E28/60 -> 0.8 | I32: =E32/6 -> 0.13333333 | K32: =E32/6 -> 0.13333333
C33: 40526 | D33: HUEVO ORO KOSHER X 30 UND | E33: =+NOTIFICACION!E29/30 -> #VALUE! | I33: =E33/10 -> #VALUE! | K33: =E33/10 -> #VALUE!
C34: 40537 | D34: HUEVOS ORO PLUS AA X 30 | E34: =+NOTIFICACION!#REF!/30 -> #REF! | I34: =E34/10 -> #REF! | K34: =E34/10 -> #REF!
C35: 40538 | D35: HUEVOS ORO AA PLUS CRISTAL X 15 | F35: =+NOTIFICACION!E30/15 -> 7.4 | K35: =F35/24 -> 0.30833333
C36: 40668 | D36: CAMPESINO TERMOENCOGIDO ORO A X 30 | E36: =+NOTIFICACION!E31/30 -> 1 | I36: =E36/10 -> 0.1 | K36: =E36/10 -> 0.1
C37: 40789 | D37: HUEVOS A X 30 AMARRADO OLIMPICA | G37: =+NOTIFICACION!E32/30 -> #VALUE! | J37: =G37/168 -> #VALUE!
C38: 40790 | D38: HUEVOS B X 30 AMARRADO OLIMPICA | G38: =+NOTIFICACION!#REF!/30 -> #REF! | J38: =G38/168 -> #REF!
